Workbook

Sheet POA&M Metrics
B3: Plan of Action & Milestones (POA&M) Metrics
B4: Version 6.1.4, Dated March 11, 2026
A8: ADMINISTERING ENTITY: | B8: ='POA&M Template'!C6 -> 0
A9: SYSTEM NAME: | B9: ='POA&M Template'!C7 -> 0
A10: SYSTEM ACRONYM: | B10: ='POA&M Template'!C8 -> 0
A11: CURRENT FISCAL YEAR: | B11: ='POA&M Template'!C9 -> 0
D13: Number of Findings by ARC-AMPE Control Family
A15: POA&M Findings Totals | D15: Control Family | E15: Total OPEN | F15: Ongoing | G15: Delayed | H15: Risk Accepted | I15: Completed
A16: POA&M Findings Status | D16: AC | E16: =SUM(F16:H16) -> 0 | F16: =SUM(COUNTIFS('POA&M Template'!$N$17:$N$5040, "Ongoing",'POA&M Template'!$B$17:$B$5040, "AC")) -> 0 | G16: =SUM(COUNTIFS('POA&M Template'!$N$17:$N$5040, "Delayed",'POA&M Template'!$B$17:$B$5040, "AC")) -> 0 | H16: =SUM(COUNTIFS('POA&M Template'!$N$17:$N$5040, "Risk Accepted",'POA&M Template'!$B$17:$B$5040, "AC")) -> 0 | I16: =SUM(COUNTIFS('POA&M Template'!$N$17:$N$5040, "Completed",'POA&M Template'!$B$17:$B$5040, "AC")) -> 0
A17: ONGOING | B17: =COUNTIF('POA&M Template'!$N$17:$N$5040, "Ongoing") -> 0 | D17: AT | E17: =SUM(F17:H17) -> 0 | F17: =SUM(COUNTIFS('POA&M Template'!$N$17:$N$5040, "Ongoing",'POA&M Template'!$B$17:$B$5040, "AT")) -> 0 | G17: =SUM(COUNTIFS('POA&M Template'!$N$17:$N$5040, "Delayed",'POA&M Template'!$B$17:$B$5040, "AT")) -> 0 | H17: =SUM(COUNTIFS('POA&M Template'!$N$17:$N$5040, "Risk Accepted",'POA&M Template'!$B$17:$B$5040, "AT")) -> 0 | I17: =SUM(COUNTIFS('POA&M Template'!$N$17:$N$5040, "Completed",'POA&M Template'!$B$17:$B$5040, "AT")) -> 0
A18: DELAYED | B18: =COUNTIF('POA&M Template'!$N$17:$N$5040, "Delayed") -> 0 | D18: AU | E18: =SUM(F18:H18) -> 0 | F18: =SUM(COUNTIFS('POA&M Template'!$N$17:$N$5040, "Ongoing",'POA&M Template'!$B$17:$B$5040, "AU")) -> 0 | G18: =SUM(COUNTIFS('POA&M Template'!$N$17:$N$5040, "Delayed",'POA&M Template'!$B$17:$B$5040, "AU")) -> 0 | H18: =SUM(COUNTIFS('POA&M Template'!$N$17:$N$5040, "Risk Accepted",'POA&M Template'!$B$17:$B$5040, "AU")) -> 0 | I18: =SUM(COUNTIFS('POA&M Template'!$N$17:$N$5040, "Completed",'POA&M Template'!$B$17:$B$5040, "AU")) -> 0
A19: RISK ACCEPTED | B19: =COUNTIF('POA&M Template'!$N$17:$N$5040, "Risk Accepted") -> 0 | D19: CA | E19: =SUM(F19:H19) -> 0 | F19: =SUM(COUNTIFS('POA&M Template'!$N$17:$N$5040, "Ongoing",'POA&M Template'!$B$17:$B$5040, "CA")) -> 0 | G19: =SUM(COUNTIFS('POA&M Template'!$N$17:$N$5040, "Delayed",'POA&M Template'!$B$17:$B$5040, "CA")) -> 0 | H19: =SUM(COUNTIFS('POA&M Template'!$N$17:$N$5040, "Risk Accepted",'POA&M Template'!$B$17:$B$5040, "CA")) -> 0 | I19: =SUM(COUNTIFS('POA&M Template'!$N$17:$N$5040, "Completed",'POA&M Template'!$B$17:$B$5040, "CA")) -> 0
A20: COMPLETED | B20: =COUNTIF('POA&M Template'!$N$17:$N$5040, "Completed") -> 0 | D20: CM | E20: =SUM(F20:H20) -> 0 | F20: =SUM(COUNTIFS('POA&M Template'!$N$17:$N$5040, "Ongoing",'POA&M Template'!$B$17:$B$5040, "CM")) -> 0 | G20: =SUM(COUNTIFS('POA&M Template'!$N$17:$N$5040, "Delayed",'POA&M Template'!$B$17:$B$5040, "CM")) -> 0 | H20: =SUM(COUNTIFS('POA&M Template'!$N$17:$N$5040, "Risk Accepted",'POA&M Template'!$B$17:$B$5040, "CM")) -> 0 | I20: =SUM(COUNTIFS('POA&M Template'!$N$17:$N$5040, "Completed",'POA&M Template'!$B$17:$B$5040, "CM")) -> 0
A21: Total | B21: =SUM(B17:B20) -> 0 | D21: CP | E21: =SUM(F21:H21) -> 0 | F21: =SUM(COUNTIFS('POA&M Template'!$N$17:$N$5040, "Ongoing",'POA&M Template'!$B$17:$B$5040, "CP")) -> 0 | G21: =SUM(COUNTIFS('POA&M Template'!$N$17:$N$5040, "Delayed",'POA&M Template'!$B$17:$B$5040, "CP")) -> 0 | H21: =SUM(COUNTIFS('POA&M Template'!$N$17:$N$5040, "Risk Accepted",'POA&M Template'!$B$17:$B$5040, "CP")) -> 0 | I21: =SUM(COUNTIFS('POA&M Template'!$N$17:$N$5040, "Completed",'POA&M Template'!$B$17:$B$5040, "CP")) -> 0
D22: IA | E22: =SUM(F22:H22) -> 0 | F22: =SUM(COUNTIFS('POA&M Template'!$N$17:$N$5040, "Ongoing",'POA&M Template'!$B$17:$B$5040, "IA")) -> 0 | G22: =SUM(COUNTIFS('POA&M Template'!$N$17:$N$5040, "Delayed",'POA&M Template'!$B$17:$B$5040, "IA")) -> 0 | H22: =SUM(COUNTIFS('POA&M Template'!$N$17:$N$5040, "Risk Accepted",'POA&M Template'!$B$17:$B$5040, "IA")) -> 0 | I22: =SUM(COUNTIFS('POA&M Template'!$N$17:$N$5040, "Completed",'POA&M Template'!$B$17:$B$5040, "IA")) -> 0
A23: Open Findings by Risk Level | D23: IR | E23: =SUM(F23:H23) -> 0 | F23: =SUM(COUNTIFS('POA&M Template'!$N$17:$N$5040, "Ongoing",'POA&M Template'!$B$17:$B$5040, "IR")) -> 0 | G23: =SUM(COUNTIFS('POA&M Template'!$N$17:$N$5040, "Delayed",'POA&M Template'!$B$17:$B$5040, "IR")) -> 0 | H23: =SUM(COUNTIFS('POA&M Template'!$N$17:$N$5040, "Risk Accepted",'POA&M Template'!$B$17:$B$5040, "IR")) -> 0 | I23: =SUM(COUNTIFS('POA&M Template'!$N$17:$N$5040, "Completed",'POA&M Template'!$B$17:$B$5040, "IR")) -> 0
A24: CRITICAL | B24: {=SUM(COUNTIFS('POA&M Template'!$O$17:$O$5040, "Critical",'POA&M Template'!$N$17:$N$5040, {"Ongoing","Delayed","Risk Accepted"}))} -> 0 | D24: MA | E24: =SUM(F24:H24) -> 0 | F24: =SUM(COUNTIFS('POA&M Template'!$N$17:$N$5040, "Ongoing",'POA&M Template'!$B$17:$B$5040, "MA")) -> 0 | G24: =SUM(COUNTIFS('POA&M Template'!$N$17:$N$5040, "Delayed",'POA&M Template'!$B$17:$B$5040, "MA")) -> 0 | H24: =SUM(COUNTIFS('POA&M Template'!$N$17:$N$5040, "Risk Accepted",'POA&M Template'!$B$17:$B$5040, "MA")) -> 0 | I24: =SUM(COUNTIFS('POA&M Template'!$N$17:$N$5040, "Completed",'POA&M Template'!$B$17:$B$5040, "MA")) -> 0
A25: HIGH | B25: {=SUM(COUNTIFS('POA&M Template'!$O$17:$O$5040, "High",'POA&M Template'!$N$17:$N$5040, {"Ongoing","Delayed","Risk Accepted"}))} -> 0 | D25: MP | E25: =SUM(F25:H25) -> 0 | F25: =SUM(COUNTIFS('POA&M Template'!$N$17:$N$5040, "Ongoing",'POA&M Template'!$B$17:$B$5040, "MP")) -> 0 | G25: =SUM(COUNTIFS('POA&M Template'!$N$17:$N$5040, "Delayed",'POA&M Template'!$B$17:$B$5040, "MP")) -> 0 | H25: =SUM(COUNTIFS('POA&M Template'!$N$17:$N$5040, "Risk Accepted",'POA&M Template'!$B$17:$B$5040, "MP")) -> 0 | I25: =SUM(COUNTIFS('POA&M Template'!$N$17:$N$5040, "Completed",'POA&M Template'!$B$17:$B$5040, "MP")) -> 0
A26: MODERATE | B26: {=SUM(COUNTIFS('POA&M Template'!$O$17:$O$5040, "Moderate",'POA&M Template'!$N$17:$N$5040, {"Ongoing","Delayed","Risk Accepted"}))} -> 0 | D26: PE | E26: =SUM(F26:H26) -> 0 | F26: =SUM(COUNTIFS('POA&M Template'!$N$17:$N$5040, "Ongoing",'POA&M Template'!$B$17:$B$5040, "PE")) -> 0 | G26: =SUM(COUNTIFS('POA&M Template'!$N$17:$N$5040, "Delayed",'POA&M Template'!$B$17:$B$5040, "PE")) -> 0 | H26: =SUM(COUNTIFS('POA&M Template'!$N$17:$N$5040, "Risk Accepted",'POA&M Template'!$B$17:$B$5040, "PE")) -> 0 | I26: =SUM(COUNTIFS('POA&M Template'!$N$17:$N$5040, "Completed",'POA&M Template'!$B$17:$B$5040, "PE")) -> 0
A27: LOW | B27: {=SUM(COUNTIFS('POA&M Template'!$O$17:$O$5040, "Low",'POA&M Template'!$N$17:$N$5040, {"Ongoing","Delayed","Risk Accepted"}))} -> 0 | D27: PL | E27: =SUM(F27:H27) -> 0 | F27: =SUM(COUNTIFS('POA&M Template'!$N$17:$N$5040, "Ongoing",'POA&M Template'!$B$17:$B$5040, "PL")) -> 0 | G27: =SUM(COUNTIFS('POA&M Template'!$N$17:$N$5040, "Delayed",'POA&M Template'!$B$17:$B$5040, "PL")) -> 0 | H27: =SUM(COUNTIFS('POA&M Template'!$N$17:$N$5040, "Risk Accepted",'POA&M Template'!$B$17:$B$5040, "PL")) -> 0 | I27: =SUM(COUNTIFS('POA&M Template'!$N$17:$N$5040, "Completed",'POA&M Template'!$B$17:$B$5040, "PL")) -> 0
A28: Total | B28: =SUM(B24:B27) -> 0 | D28: PM | E28: =SUM(F28:H28) -> 0 | F28: =SUM(COUNTIFS('POA&M Template'!$N$17:$N$5040, "Ongoing",'POA&M Template'!$B$17:$B$5040, "PM")) -> 0 | G28: =SUM(COUNTIFS('POA&M Template'!$N$17:$N$5040, "Delayed",'POA&M Template'!$B$17:$B$5040, "PM")) -> 0 | H28: =SUM(COUNTIFS('POA&M Template'!$N$17:$N$5040, "Risk Accepted",'POA&M Template'!$B$17:$B$5040, "PM")) -> 0 | I28: =SUM(COUNTIFS('POA&M Template'!$N$17:$N$5040, "Completed",'POA&M Template'!$B$17:$B$5040, "PM")) -> 0
D29: PS | E29: =SUM(F29:H29) -> 0 | F29: =SUM(COUNTIFS('POA&M Template'!$N$17:$N$5040, "Ongoing",'POA&M Template'!$B$17:$B$5040, "PS")) -> 0 | G29: =SUM(COUNTIFS('POA&M Template'!$N$17:$N$5040, "Delayed",'POA&M Template'!$B$17:$B$5040, "PS")) -> 0 | H29: =SUM(COUNTIFS('POA&M Template'!$N$17:$N$5040, "Risk Accepted",'POA&M Template'!$B$17:$B$5040, "PS")) -> 0 | I29: =SUM(COUNTIFS('POA&M Template'!$N$17:$N$5040, "Completed",'POA&M Template'!$B$17:$B$5040, "PS")) -> 0
A30: Total# of Open Findings (Ongoing, Delayed & Risk Accepted) | B30: =SUM(B17:B19) -> 0 | D30: PT | E30: =SUM(F30:H30) -> 0 | F30: =SUM(COUNTIFS('POA&M Template'!$N$17:$N$5040, "Ongoing",'POA&M Template'!$B$17:$B$5040, "PT")) -> 0 | G30: =SUM(COUNTIFS('POA&M Template'!$N$17:$N$5040, "Delayed",'POA&M Template'!$B$17:$B$5040, "PT")) -> 0 | H30: =SUM(COUNTIFS('POA&M Template'!$N$17:$N$5040, "Risk Accepted",'POA&M Template'!$B$17:$B$5040, "PT")) -> 0 | I30: =SUM(COUNTIFS('POA&M Template'!$N$17:$N$5040, "Completed",'POA&M Template'!$B$17:$B$5040, "PT")) -> 0
D31: RA | E31: =SUM(F31:H31) -> 0 | F31: =SUM(COUNTIFS('POA&M Template'!$N$17:$N$5040, "Ongoing",'POA&M Template'!$B$17:$B$5040, "RA")) -> 0 | G31: =SUM(COUNTIFS('POA&M Template'!$N$17:$N$5040, "Delayed",'POA&M Template'!$B$17:$B$5040, "RA")) -> 0 | H31: =SUM(COUNTIFS('POA&M Template'!$N$17:$N$5040, "Risk Accepted",'POA&M Template'!$B$17:$B$5040, "RA")) -> 0 | I31: =SUM(COUNTIFS('POA&M Template'!$N$17:$N$5040, "Completed",'POA&M Template'!$B$17:$B$5040, "RA")) -> 0
D32: SA | E32: =SUM(F32:H32) -> 0 | F32: =SUM(COUNTIFS('POA&M Template'!$N$17:$N$5040, "Ongoing",'POA&M Template'!$B$17:$B$5040, "SA")) -> 0 | G32: =SUM(COUNTIFS('POA&M Template'!$N$17:$N$5040, "Delayed",'POA&M Template'!$B$17:$B$5040, "SA")) -> 0 | H32: =SUM(COUNTIFS('POA&M Template'!$N$17:$N$5040, "Risk Accepted",'POA&M Template'!$B$17:$B$5040, "SA")) -> 0 | I32: =SUM(COUNTIFS('POA&M Template'!$N$17:$N$5040, "Completed",'POA&M Template'!$B$17:$B$5040, "SA")) -> 0
D33: SC | E33: =SUM(F33:H33) -> 0 | F33: =SUM(COUNTIFS('POA&M Template'!$N$17:$N$5040, "Ongoing",'POA&M Template'!$B$17:$B$5040, "SC")) -> 0 | G33: =SUM(COUNTIFS('POA&M Template'!$N$17:$N$5040, "Delayed",'POA&M Template'!$B$17:$B$5040, "SC")) -> 0 | H33: =SUM(COUNTIFS('POA&M Template'!$N$17:$N$5040, "Risk Accepted",'POA&M Template'!$B$17:$B$5040, "SC")) -> 0 | I33: =SUM(COUNTIFS('POA&M Template'!$N$17:$N$5040, "Completed",'POA&M Template'!$B$17:$B$5040, "SC")) -> 0
D34: SI | E34: =SUM(F34:H34) -> 0 | F34: =SUM(COUNTIFS('POA&M Template'!$N$17:$N$5040, "Ongoing",'POA&M Template'!$B$17:$B$5040, "SI")) -> 0 | G34: =SUM(COUNTIFS('POA&M Template'!$N$17:$N$5040, "Delayed",'POA&M Template'!$B$17:$B$5040, "SI")) -> 0 | H34: =SUM(COUNTIFS('POA&M Template'!$N$17:$N$5040, "Risk Accepted",'POA&M Template'!$B$17:$B$5040, "SI")) -> 0 | I34: =SUM(COUNTIFS('POA&M Template'!$N$17:$N$5040, "Completed",'POA&M Template'!$B$17:$B$5040, "SI")) -> 0
D35: SR | E35: =SUM(F35:H35) -> 0 | F35: =SUM(COUNTIFS('POA&M Template'!$N$17:$N$5040, "Ongoing",'POA&M Template'!$B$17:$B$5040, "SR")) -> 0 | G35: =SUM(COUNTIFS('POA&M Template'!$N$17:$N$5040, "Delayed",'POA&M Template'!$B$17:$B$5040, "SR")) -> 0 | H35: =SUM(COUNTIFS('POA&M Template'!$N$17:$N$5040, "Risk Accepted",'POA&M Template'!$B$17:$B$5040, "SR")) -> 0 | I35: =SUM(COUNTIFS('POA&M Template'!$N$17:$N$5040, "Completed",'POA&M Template'!$B$17:$B$5040, "SR")) -> 0
D36: Other | E36: =SUM(F36:H36) -> 0 | F36: =SUM(COUNTIFS('POA&M Template'!$N$17:$N$5040, "Ongoing",'POA&M Template'!$B$17:$B$5040, "Other")) -> 0 | G36: =SUM(COUNTIFS('POA&M Template'!$N$17:$N$5040, "Delayed",'POA&M Template'!$B$17:$B$5040, "Other")) -> 0 | H36: =SUM(COUNTIFS('POA&M Template'!$N$17:$N$5040, "Risk Accepted",'POA&M Template'!$B$17:$B$5040, "Other")) -> 0 | I36: =SUM(COUNTIFS('POA&M Template'!$N$17:$N$5040, "Completed",'POA&M Template'!$B$17:$B$5040, "Other")) -> 0

Sheet POA&M Template
B3: Plan of Action & Milestones (POA&M)
B4: ='POA&M Metrics'!B4 -> Version 6.1.4, Dated March 11, 2026
A6: ADMINISTERING ENTITY:
A7: SYSTEM NAME:
A8: SYSTEM ACRONYM:
A9: CURRENT FISCAL YEAR:
A12: System Name | C12: System Acronym | D12: System Criticality as defined by FIPS | F12: Confidentiality | H12: Availability | I12: Integrity | J12: If no findings identified, provide a reason | O12: Risk Subtotal
A13: =C7 -> 0 | C13: =C8 -> 0 | D13: Moderate | F13: Moderate | H13: Moderate | I13: Moderate | O13: =SUBTOTAL(3,$O$17:$O$5040) -> 0
A16: Finding Identifier | B16: ARC-AMPE Control Family | C16: Control Details | D16: Finding Description | E16: Affected Host(s) (For Technical Findings Only) | F16: Finding Source | G16: POC | H16: Resources Required | I16: Initial Scheduled Completion Date | J16: Milestones With Completion Dates | K16: Changes to Milestones with Completion Dates | L16: Updated Scheduled Completion Date | M16: Actual Completion Date | N16: Finding Status | O16: Risk Level | P16: Risk Acceptance Form Title (if Risk Accepted) | Q16: ARC-AMPE Version | R16: Compensating Controls | S16: Comments

Sheet Vulnerability Tracking
M2: RA-05 Vulnerability Remediation Timelines (also applies to SI-02 Flaw Remediation)
H3: Plan of Action & Milestones (POA&M)
H4: ='POA&M Metrics'!B4 -> Version 6.1.4, Dated March 11, 2026 | M4: Critical severity within fifteen (15) calendar days
M5: High severity within thirty (30) calendar days
G6: Instructions: | H6: This tab is Optional, and its format defaults to Nessus output but can be modified to accommodate other tools. | M6: Moderate severity within ninety (90) calendar days
H7: Populate this section with open vulnerabilities that have not been or cannot be mediated within the guidelines | M7: Low severity within one (1) year
H8: established in both RA-05, Vulnerability Monitoring and Scanning, and SI-02, Flaw Remediation.
H9: In column D, Status, select from the drop-down list (Open, Open / RA, Closed, False Positive, or Reopened)
B11: Leave columns A-C unchanged | D11: Columns D-O headers default to Nessus output, but can be modified as needed
A12: Vulnerability # | B12: CVE | C12: POAM ID | D12: Status | E12: Plugin | F12: Plugin Name | G12: Severity | H12: IP Address or Host Name | I12: Repository | J12: DNS Name | K12: Plugin Output | L12: Description | M12: Solution | N12: First Discovered | O12: Last Observed

Sheet POA&M Instructions
A6: ADMINISTERING ENTITY:
A7: SYSTEM NAME:
A8: SYSTEM ACRONYM:
A9: CURRENT FISCAL YEAR:
A12: System Name | C12: System Acronym | D12: System Criticality as defined by FIPS | F12: Confidentiality | H12: Availability | I12: Integrity | J12: If no findings identified, provide a reason
A13: =#REF! -> #REF! | D13: Moderate | F13: Moderate | H13: Moderate | I13: Moderate
A16: Finding Identifier | B16: Control Family | C16: Control Details | D16: Finding Description | E16: Affected Host(s) (for Technical Findings Only) | F16: Finding Source | G16: POC | H16: Resources Required | I16: Initial Scheduled Completion Date | J16: Milestones With Completion Dates | K16: Changes to Milestones Date | L16: Updated Scheduled Completion Date | M16: Actual Completion Date | N16: Finding Status | O16: Risk Level | P16: ARC-AMPE Version | Q16: Compensating Controls | R16: Comments

Sheet Risk Calculation Instructions
A9: From Appendix G
A11: Likelihood of Occurrence
A13: Table G-2: Assessment Scale - Likelihood of Threat Event Initiation (Adversarial)
A14: Qualitative Values | B14: Semi-Quantitative Values | D14: Description
A15: Critical | B15: 96-100 | C15: 10 | D15: Adversary is almost certain to initiate the threat event.
A16: High | B16: 80-95 | C16: 8 | D16: Adversary is highly likely to initiate the threat event.
A17: Moderate | B17: 21-79 | C17: 5 | D17: Adversary is somewhat likely to initiate the treat event.
A18: Low | B18: 5-20 | C18: 2 | D18: Adversary is unlikely to initiate the threat event.
A19: Very Low | B19: 0-4 | C19: 0 | D19: Adversary is highly unlikely to initiate the threat event.
A22: Table G-3: Assessment Scale - Likelihood of Threat Event Occurrence (Non-Adversarial)
A23: Qualitative Values | B23: Semi-Quantitative Values | D23: Description
A24: Critical | B24: 96-100 | C24: 10 | D24: Error, accident, or act of nature is almost certain to occur; or occurs more than 100 times a year.
A25: High | B25: 80-95 | C25: 8 | D25: Error, accident, or act of nature is highly likely to occur; or occurs between 10-100 times a year.
A26: Moderate | B26: 21-79 | C26: 5 | D26: Error, accident, or act of nature is somewhat likely to occur; or occurs between 1-10 times a year.
A27: Low | B27: 5-20 | C27: 2 | D27: Error, accident, or act of nature is unlikely to occur; or occurs less than once a year, but more than once every 10 years.
A28: Very Low | B28: 0-4 | C28: 0 | D28: Error, accident, or act of nature is highly unlikely to occur; or occurs less than once every 10 years.
A31: Table G-4: Assessment Scale - Likelihood of Threat Event Resulting in Adverse Impacts
A32: Qualitative Values | B32: Semi-Quantitative Values | D32: Description
A33: Critical | B33: 96-100 | C33: 10 | D33: If the threat event is initiated or occurs, it is almost certain to have adverse impacts.
A34: High | B34: 80-95 | C34: 8 | D34: If the threat event is initiated or occurs, it is highly likely to have adverse impacts.
A35: Moderate | B35: 21-79 | C35: 5 | D35: If the threat event is initiated or occurs, it is somewhat likely to have adverse impacts.
A36: Low | B36: 5-20 | C36: 2 | D36: If the threat event is initiated or occurs, it is unlikely to have adverse impacts.
A37: Very Low | B37: 0-4 | C37: 0 | D37: If the threat event is initiated or occurs, it is highly unlikely to have adverse impacts.
A40: Table G-5: Assessment Scale - Overall Likelihood
A41: Likelihood of Threat Event Initiation or Occurrence | B41: Likelihood Threat Events Result in Adverse Impacts
B43: Very Low | C43: Low | D43: Moderate | E43: High | F43: Critical
A44: Critical | B44: Low | C44: Moderate | D44: High | E44: Very High | F44: Critical
A45: High | B45: Low | C45: Moderate | D45: Moderate | E45: High | F45: Critical
A46: Moderate | B46: Low | C46: Low | D46: Moderate | E46: Moderate | F46: High
A47: Low | B47: Very Low | C47: Low | D47: Low | E47: Moderate | F47: Moderate
A48: Very Low | B48: Very Low | C48: Very Low | D48: Low | E48: Low | F48: Low
A51: From Appendix H
A53: Impact
A56: Table H-2: Examples of Adverse Impacts
A57: Type of Impact | C57: Impact
A58: Harm to Operations | C58: (1) Inability to perform current missions/business functions. -In a sufficiently timely manner. -With sufficient confidence and/or correctness. -Within planned resource constraints (2) Inability, or limited ability, to perform missions/business functions in the future. -Inability to restore missions/business functions. -In a sufficiently timely manner. -With sufficient confidence and/or correctness. -Within planned resource constraints. (3) Harms (e.g., financial costs, sanctions) due to noncompliance. -With applicable laws or regulations. -With contractual requirements or other requirements in other binding agreements (e.g., liability). (4) Direct financial costs. (5) Relational harms. -Damage to trust relationships. -Damage to image or reputation (and hence future or potential trust relationships).
A59: Harm to Assets | C59: (1) Damage to or loss of physical facilities. (2) Damage to or loss of information systems or networks. (3) Damage to or loss of information technology or equipment. (4) Damage to or loss of component parts or supplies. (5) Damage to or of loss of information assets. (6) Loss of intellectual property.
A60: Harm to Individuals | C60: (1) Injury or loss of life. (2) Physical or psychological mistreatment. (3) Identity theft. (4) Loss of Personally Identifiable Information. (5) Damage to image or reputation.
A61: Harm to Other Organizations | C61: (1) Harms (e.g., financial costs, sanctions) due to noncompliance. -With applicable laws or regulations. -With contractual requirements or other requirements in other binding agreements. (2) Direct financial costs. (3) Relational harms -Damage to trust relationships. -Damage to reputation (and hence future or potential trust relationships).
A62: Harm to Nation | C62: (1) Damage to or incapacitation of a critical infrastructure sector. (2) Loss of government continuity of operations. (3) Relational harms. -Damage to trust relationships with other governments or with nongovernmental entities. -Damage to national reputation (and hence future or potential trust relationships). (4) Damage to current or future ability to achieve national objectives. -Harm to national security.
...

Sheet POA&M Sample
A7: ADMINISTERING ENTITY: | C7: Virginia
A8: SYSTEM NAME: | C8: VA Test System
A9: SYSTEM ACRONYM: | C9: VATESTSYS
A10: CURRENT FISCAL YEAR: | C10: 2025
A13: System Name | C13: System Acronym | D13: System Critically as defined by FIPS | F13: Confidentiality | H13: Availability | I13: Integrity | J13: If no weaknesses identified, provide a reason
A14: =C8 -> VA Test System | C14: =C9 -> VATESTSYS | D14: Moderate | F14: Moderate | H14: Moderate | I14: Moderate
A17: Finding Identifier | B17: ARC-AMPE Control Family | C17: Control Details | D17: Finding Description | E17: Affected Host(s) (For Technical Findings Only) | F17: Finding Source | G17: POC | H17: Resources Required | I17: Initial Scheduled Completion Date | J17: Milestones With Completion Dates | K17: Changes to Milestones Date | L17: Updated Scheduled Completion Date | M17: Actual Completion Date | N17: Finding Status | O17: Risk Level | P17: Risk Acceptance Form Title (if Risk Accepted) | Q17: ARC-AMPE Version | R17: Compensating Controls | S17: Comments
A18: TESTSYS_A_2024_1 | B18: AC | C18: AC-02 | D18: Account Management process is not documented. | E18: N/A | F18: Initial Security Assessment Review 02/12/2024 | G18: John Doe, CISO | H18: 8 hours Existing Staff | I18: 46096 | J18: (1) Create an account management process 2/28/2024 (2) Document process 03/01/2024 (3) Review process with staff 03/10/2024 (4) Implement Process 03/12/2024 (5) Review effective of new process 03/14/2024 (6) Update POA&M 03/15/2024 | K18: (1) Create an account management process 2/15/2024 (2) Document process 02/20/2024 (3) Review process with staff 02/25/2024 (4) Implement Process 02/26/2024 (5) Review effective of new process 02/28/2024 (6) Update POA&M 03/01/2024 | M18: 45352 | N18: Completed | O18: Moderate | Q18: ARC-AMPE v1.0x | R18: N/A
A19: TESTSYS_A_2024_2 | B19: PE | C19: PE-10 | D19: There is no EPO in server room 1. | E19: Server room 1 | F19: Initial Security Assessment Review 02/12/2024 | G19: John Doe, CISO | H19: 20 hours Existing Staff $65,000 Professional Services and Equipment | I19: 46235 | J19: (1) Solicit vendors to provide EPO solution and estimate of cost 02/25/2024 (2) Choose vendor to perform work 04/15/2024 (3) Initiate the install of the emergency power shutoff solution 07/01/2024 (4) Test the implemented EPO solution 07/15/2024 (5) Finalize solution and update POA&M 08/01/2024 | K19: (3) Initiate the install of the emergency power shutoff solution NEW DATE 05/01/2024 (4) Test the implemented EPO solution 05/15/2024 (5) Finalize solution and update POA&M 06/01/2024 | N19: Delayed | O19: Moderate | Q19: ARC-AMPE v1.0x | R19: N/A | S19: Awaiting funding to implement EPO solution
A20: TESTSYS_A_2024_2 | B20: IA | C20: IA-05 | D20: Update the control implementation statement to document the processes used to implement control requirements a-f, h, and i. | E20: N/A | F20: SSPP Review 06/10/2024 | G20: John Doe, CISO | H20: 10 hours Existing Staff | I20: 46233 | J20: (1) Update the implementation standards a-f, h, and I for IA-5 in the SSPP 06/20/2024 (2) Review changes to the SSPP with the security staff 07/01/2024 (3) Finalize the implementation standards based on staff comments and recommendations 07/30/2024 | M20: 45503 | N20: Completed | O20: Low | Q20: ARC-AMPE v1.0x | R20: N/A
A21: TESTSYS_A_2024_3 | B21: PE | C21: PE6.2 | D21: Lack of processes for: (a) reviewing physical access logs at least once every two months, and (b) coordinating results of reviews and investigations with the organization's incident response capability. | E21: N/A | F21: Annual Attestation 03/01/2024 | G21: John Doe, CISO | H21: 20 hours Existing Staff | I21: 46162 | J21: (1) Create a process reviewing physical access logs at least once every two months and coordinating results of reviews and investigations with the organization's incident response capability: 3/8/2024 (2) Document process 04/01/2024 (3) Review process with staff 04/15/2024 (4) Implement Process 05/01/2024 (5) Review effective of new process 05/15/2024 (6) Update POA&M 05/20/2024 | N21: Ongoing | O21: Low | Q21: ARC-AMPE v1.0x | R21: N/A
A22: TESTSYS_A_2024_4 | B22: SI | C22: SI-02 | D22: Windows server BD1-3 has not been patched in 3 months | E22: Windows server BD1-3 | F22: Annual Attestation 03/01/2024 | G22: John Doe, CISO | H22: 40 hours Existing Staff | I22: 46096 | J22: (1) Develop a plan and schedule to patch the servers monthly. Update the SSPP to reflect the plan to patch the servers 03/15/2024 (2) Test the outstanding patches in the test environment (3) Implement patches on the production server | K22: (2) continuing testing in the test environment (3) Implement patches on the production server | N22: Delayed | O22: High | Q22: ARC-AMPE v1.0x | R22: N/A | S22: Need additional testing due to possible adverse affects of applying the patch. MS14-013 (KB2929961)
A23: TESTSYS_A_2024_5 | B23: RA | C23: RA-05 | D23: The organization does not employ vulnerability scanning tools | E23: All servers/workstations | F23: Annual Attestation 03/01/2024 | G23: John Doe, CISO | H23: 80 hours Existing Staff $3000 Tools and Training | I23: 46113 | J23: (1) Shop vulnerability scanning tools 03/05/2024 (2) Select vulnerability scanning tool 03/10/2024 (3) Obtain training on the product 03/15/2024 (4) Test product in the test environment 03/20/2024 (5) Implement solution in production and monitor 04/01/2024 | N23: Ongoing | O23: High | Q23: ARC-AMPE v1.0x | R23: N/A
A24: TESTSYS_A_2025_1 | B24: CM | C24: CM-06(01) | D24: Manual management, application, and verification of configurations and software creates risk of misconfigurations. | E24: Windows server BD1-2 | F24: Independent Assessment: John Doe, 1/23/2026 | G24: John Doe, CISO | H24: 8 hours, patch automation software | I24: 46038 | J24: (1) Complete Internal Security Risk Assessment - 12/9/2025 (2) Review Risk and Determine Acceptance - 12/12/2025 1/16/2026 - Performed annual Risk Acceptance review | N24: Risk Accepted | O24: Low | P24: 2026-RA-CM-06(01) | Q24: ARC-AMPE v1.0x | R24: Configuration management is governed by strict security and change controls: Access Control: Configuration can only be performed by a privileged administrator account user. Access is protected by firewalls to prevent unauthorized external changes to the production environment. Monitoring and Review: A manual review process uses audit log monitoring to detect and confirm any changes. Versioning and Recovery: All configurations are baselined and stored. In the event of an unintended or unplanned change, this approved baseline is used to restore the configuration. | S24: All configuration updates are manually validated with test scenarios against baseline checks to ensure system functionality. The organization accepts the outlined risk and will continue to evaluate automated processes as funding becomes available.

Sheet Data Sheet
A1: Finding Status | B1: Risk Level | C1: No weaknesses identified | D1: Fiscal Year | E1: Control | F1: ARC-AMPE Version | G1: Status
A3: Ongoing | B3: Critical | C3: All weaknesses eliminated | D3: 2024 | E3: AC | F3: ARC-AMPE v1.0x | G3: Open
A4: Completed | B4: High | C4: No review conducted | D4: 2025 | E4: AT | G4: Open / RA
A5: Delayed | B5: Moderate | C5: No weaknesses found | D5: 2026 | E5: AU | G5: Closed
A6: Risk Accepted | B6: Low | C6: System in development | D6: 2027 | E6: CA | G6: False Positive
C7: System reclassified – not a system | D7: 2028 | E7: CM | G7: Reopened
C8: System retired | D8: 2029 | E8: CP
D9: 2030 | E9: IA
D10: 2031 | E10: IR
D11: 2032 | E11: MA
D12: 2033 | E12: MP
D13: 2034 | E13: PE
E14: PL
E15: PM
E16: PS
E17: PT
E18: RA
E19: SA
E20: SC
E21: SI
E22: SR
E23: Other

Sheet Change Log 
A1: Record of Changes
A2: Number | B2: Date | C2: Reference | D2: A = Add M = Modify D = Delete | E2: Description of Change | F2: Substantive Change [Y/N]
A3: 6.0 | B3: 45582 | D3: M | E3: New version for ARC-AMPE. Removed MARS-E references. | F3: Y
A4: 6.1 | B4: 45757 | D4: M | E4: Added Vulnerability Tracking tab for adding open vulnerabilities to include as POA&M entries. | F4: Y
A5: 6.1.1 | B5: 45825 | D5: M | E5: In Vulnerability Tracking tab, added a Status column with drop-down list. | F5: N
A6: 6.1.2 | B6: 45959 | D6: M | E6: Added Other as a control dropdown selection. Added instruction that a partially implemented control is a finding to list and track. Referenced SI-02 in Vulnerability Tracking. | F6: N
A7: 6.1.3 | B7: 46057 | D7: M | E7: Added column to POA&M Template tab to add RA Title if finding is Risk Accepted. | F7: N
A8: 6.1.4 | B8: 46092 | D8: M | E8: Updated Vulnerability Tracking tab instructions stating it is optional to complete and columns can be tailored with the exception of A-C. | F8: N
