Workbook
Name Low: #REF!
Name Low: CtrlSummary!#REF!
Name Low: #REF!
Name Low: #REF!

Sheet Version Control
B3: Security Requirements Traceability Matrix (SRTM) Workbook
B4: Description
B5: Assessment SRTM Workbook for CMMC Level 2 C3PAO/Self Assessments
B9: Template Version Control
B10: Date | C10: Person entering change | D10: Version # | E10: Comment
B11: 45421 | C11: Thang Pham | D11: 1.0 | E11: Created from NIST SP 800-171R2 & 800-171A
B12: 45421 | C12: Thang Pham | D12: 2.0 | E12: Updated based on Final Rule and Assessment Guides
B15: Template Owner
B16: Name: | C16: Thang Pham
B17: Org: | C17: Assurit
B18: Title: | C18: Vice President
B19: Phone: | C19: 703-403-4939
B20: E-mail: | C20: Thang.Pham@assurit.onmicrosoft.us
B26: Internal
B27: External
B28: Stand-alone

Sheet System
B2: System Name | C2: Assurit Protected Information System (APIS) | F2: PRACTICE DETAILS
B3: Organization | C3: Assurit | F3: IDENTIFICATION & ACCESS MANAGEMENT | J3: CYBERSECURITY OVERSIGHT & MANAGEMENT | N3: CONFIGURATION MANAGEMENT | R3: NETWORK DEFENSE
B4: Categorization Level | C4: CMMC-L2 (Moderate)
G5: Access Control Summary | K5: Awareness & Training Summary | O5: Configuration Management Summary | S5: Incident Response Summary
B6: IMPLEMENTATION STATUS | G6: Result | H6: Count | K6: Result | L6: Count | O6: Result | P6: Count | S6: Result | T6: Count
B7: Total Practices | C7: =COUNTA(CtrlSummary!B2:B9764) -> 110 | G7: MET | H7: =COUNTIFS(CtrlSummary!A:A,"AC",CtrlSummary!F:F,"MET") -> 22 | K7: MET | L7: =COUNTIFS(CtrlSummary!A:A,"AT",CtrlSummary!F:F,"MET") -> 3 | O7: MET | P7: =COUNTIFS(CtrlSummary!A:A,"CM",CtrlSummary!F:F,"MET") -> 9 | S7: MET | T7: =COUNTIFS(CtrlSummary!A:A,"IR",CtrlSummary!F:F,"MET") -> 3
B8: Status | C8: Count | D8: % of Total Controls | G8: NOT MET | H8: =COUNTIFS(CtrlSummary!A:A,"AC",CtrlSummary!F:F,"NOT MET") -> 0 | K8: NOT MET | L8: =COUNTIFS(CtrlSummary!A:A,"AT",CtrlSummary!F:F,"NOT MET") -> 0 | O8: NOT MET | P8: =COUNTIFS(CtrlSummary!A:A,"CM",CtrlSummary!F:F,"NOT MET") -> 0 | S8: NOT MET | T8: =COUNTIFS(CtrlSummary!A:A,"IR",CtrlSummary!F:F,"NOT MET") -> 0
B9: Implemented | C9: =COUNTIFS(CtrlSummary!E:E,B9) -> 86 | D9: =C9/$C$7 -> 0.78181818
B10: Partially Implemented | C10: =COUNTIFS(CtrlSummary!E:E,B10) -> 0 | D10: =C10/$C$7 -> 0 | G10: Audit & Accountability Summary | K10: Personnel Security Summary | O10: Maintenance Summary | S10: System & Communications Protection Summary
B11: Planned | C11: =COUNTIFS(CtrlSummary!E:E,B11) -> 0 | D11: =C11/$C$7 -> 0 | G11: Result | H11: Count | K11: Result | L11: Count | O11: Result | P11: Count | S11: Result | T11: Count
B12: Inherited | C12: =COUNTIFS(CtrlSummary!E:E,B12) -> 23 | D12: =C12/$C$7 -> 0.20909091 | G12: MET | H12: =COUNTIFS(CtrlSummary!A:A,"AU",CtrlSummary!F:F,"MET") -> 9 | K12: MET | L12: =COUNTIFS(CtrlSummary!A:A,"PS",CtrlSummary!F:F,"MET") -> 2 | O12: MET | P12: =COUNTIFS(CtrlSummary!A:A,"MA",CtrlSummary!F:F,"MET") -> 6 | S12: MET | T12: =COUNTIFS(CtrlSummary!A:A,"SC",CtrlSummary!F:F,"MET") -> 16
B13: Not Selected | C13: =COUNTIFS(CtrlSummary!E:E,B13) -> 1 | D13: =C13/$C$7 -> 0.0090909091 | G13: NOT MET | H13: =COUNTIFS(CtrlSummary!A:A,"AU",CtrlSummary!F:F,"NOT MET") -> 0 | K13: NOT MET | L13: =COUNTIFS(CtrlSummary!A:A,"PS",CtrlSummary!F:F,"NOT MET") -> 0 | O13: NOT MET | P13: =COUNTIFS(CtrlSummary!A:A,"MA",CtrlSummary!F:F,"NOT MET") -> 0 | S13: NOT MET | T13: =COUNTIFS(CtrlSummary!A:A,"SC",CtrlSummary!F:F,"NOT MET") -> 0
B14: Total | C14: =SUM(C9:C13) -> 110 | D14: =C14/$C$7 -> 1
G15: Identification & Authentication Summary | K15: Physical Protection Summary | O15: Media Protection Summary | S15: System & Information Integrity Summary
B16: ASSESSMENT RESULTS (CURRENT) | G16: Result | H16: Count | K16: Result | L16: Count | O16: Result | P16: Count | S16: Result | T16: Count
B17: Result | C17: Count | D17: % of Total Controls | G17: MET | H17: =COUNTIFS(CtrlSummary!A:A,"IA",CtrlSummary!F:F,"MET") -> 11 | K17: MET | L17: =COUNTIFS(CtrlSummary!A:A,"PE",CtrlSummary!F:F,"MET") -> 6 | O17: MET | P17: =COUNTIFS(CtrlSummary!A:A,"MP",CtrlSummary!F:F,"MET") -> 9 | S17: MET | T17: =COUNTIFS(CtrlSummary!A:A,"SI",CtrlSummary!F:F,"MET") -> 7
B18: MET | C18: =COUNTIFS(CtrlSummary!F:F,B18) -> 110 | D18: =C18/($C$7-$C$21) -> 1 | G18: NOT MET | H18: =COUNTIFS(CtrlSummary!A:A,"IA",CtrlSummary!F:F,"NOT MET") -> 0 | K18: NOT MET | L18: =COUNTIFS(CtrlSummary!A:A,"PE",CtrlSummary!F:F,"NOT MET") -> 0 | O18: NOT MET | P18: =COUNTIFS(CtrlSummary!A:A,"MP",CtrlSummary!F:F,"NOT MET") -> 0 | S18: NOT MET | T18: =COUNTIFS(CtrlSummary!A:A,"SI",CtrlSummary!F:F,"NOT MET") -> 0
B19: NOT MET | C19: =COUNTIFS(CtrlSummary!F:F,B19) -> 0 | D19: =C19/($C$7-$C$21) -> 0
B20: Total | C20: =SUM(C16:C19) -> 110 | D20: =C20/$C$7 -> 1 | K20: Security Assessment Summary
K21: Result | L21: Count
B22: CMMC Practice Scoring | K22: MET | L22: =COUNTIFS(CtrlSummary!A:A,"CA",CtrlSummary!F:F,"MET") -> 4
B23: Total Practice Score | C23: =SUM(CtrlSummary!G:G) -> 110 | K23: NOT MET | L23: =COUNTIFS(CtrlSummary!A:A,"CA",CtrlSummary!F:F,"NOT MET") -> 0
B24: Total Allowable Points | C24: 110
B25: Percentage | C25: =(C23/C24) -> 1 | K25: Risk Assessment Summary
K26: Result | L26: Count
K27: MET | L27: =COUNTIFS(CtrlSummary!A:A,"RA",CtrlSummary!F:F,"MET") -> 3
K28: NOT MET | L28: =COUNTIFS(CtrlSummary!A:A,"RA",CtrlSummary!F:F,"NOT MET") -> 0

Sheet CtrlSummary
A1: Domain | B1: CMMC ID | C1: CMMC Level | D1: Practice Name | E1: Implementation Status | F1: Assessment Result | G1: Practice Scoring (+) | H1: Deductible Points (-)
D2: Access Control (AC)
A3: AC | B3: AC.L1-3.1.1 | C3: 1 | D3: Authorized Access Control | E3: =IF(COUNTIF(AC!I2:I7,"Not Selected")>0,"Not Selected", IF(COUNTIF(AC!I2:I7,"Planned")>0,"Planned", IF(COUNTIF(AC!I2:I7,"Inherited")>0,"Inherited", IF(COUNTIF(AC!I2:I7,"Partially Implemented")>0,"Partially Implemented", IF(COUNTIF(AC!I2:I7,"Implemented")>0,"Implemented", ""))))) -> Implemented | F3: =IF(COUNTIF(AC!J2:J7,"Not Applicable")>0,"Not Applicable", IF(COUNTIF(AC!J2:J7,"NOT MET")>0,"NOT MET", IF(COUNTIF(AC!J2:J7,"MET")>0,"MET", ""))) -> MET | G3: 1 | H3: 5
A4: AC | B4: AC.L1-3.1.2 | C4: 1 | D4: Transaction & Function Control | E4: =IF(COUNTIF(AC!I8:I9,"Not Selected")>0,"Not Selected", IF(COUNTIF(AC!I8:I9,"Planned")>0,"Planned", IF(COUNTIF(AC!I8:I9,"Inherited")>0,"Inherited", IF(COUNTIF(AC!I8:I9,"Partially Implemented")>0,"Partially Implemented", IF(COUNTIF(AC!I8:I9,"Implemented")>0,"Implemented", ""))))) -> Implemented | F4: =IF(COUNTIF(AC!J8:J9,"Not Applicable")>0,"Not Applicable", IF(COUNTIF(AC!J8:J9,"NOT MET")>0,"NOT MET", IF(COUNTIF(AC!J8:J9,"MET")>0,"MET", ""))) -> MET | G4: 1 | H4: 5
A5: AC | B5: AC.L2-3.1.3 | C5: 2 | D5: Control CUI Flow | E5: =IF(COUNTIF(AC!I10:I14,"Not Selected")>0,"Not Selected", IF(COUNTIF(AC!I10:I14,"Planned")>0,"Planned", IF(COUNTIF(AC!I10:I14,"Inherited")>0,"Inherited", IF(COUNTIF(AC!I10:I14,"Partially Implemented")>0,"Partially Implemented", IF(COUNTIF(AC!I10:I14,"Implemented")>0,"Implemented", ""))))) -> Implemented | F5: =IF(COUNTIF(AC!J10:J14,"Not Applicable")>0,"Not Applicable", IF(COUNTIF(AC!J10:J14,"NOT MET")>0,"NOT MET", IF(COUNTIF(AC!J10:J14,"MET")>0,"MET", ""))) -> MET | G5: 1 | H5: 1
A6: AC | B6: AC.L2-3.1.4 | C6: 2 | D6: Separation of Duties | E6: =IF(COUNTIF(AC!I15:I17,"Not Selected")>0,"Not Selected", IF(COUNTIF(AC!I15:I17,"Planned")>0,"Planned", IF(COUNTIF(AC!I15:I17,"Inherited")>0,"Inherited", IF(COUNTIF(AC!I15:I17,"Partially Implemented")>0,"Partially Implemented", IF(COUNTIF(AC!I15:I17,"Implemented")>0,"Implemented", ""))))) -> Implemented | F6: =IF(COUNTIF(AC!J15:J17,"Not Applicable")>0,"Not Applicable", IF(COUNTIF(AC!J15:J17,"NOT MET")>0,"NOT MET", IF(COUNTIF(AC!J15:J17,"MET")>0,"MET", ""))) -> MET | G6: 1 | H6: 1
A7: AC | B7: AC.L2-3.1.5 | C7: 2 | D7: Least Privilege | E7: =IF(COUNTIF(AC!I18:I21,"Not Selected")>0,"Not Selected", IF(COUNTIF(AC!I18:I21,"Planned")>0,"Planned", IF(COUNTIF(AC!I18:I21,"Inherited")>0,"Inherited", IF(COUNTIF(AC!I18:I21,"Partially Implemented")>0,"Partially Implemented", IF(COUNTIF(AC!I18:I21,"Implemented")>0,"Implemented", ""))))) -> Implemented | F7: =IF(COUNTIF(AC!J18:J21,"Not Applicable")>0,"Not Applicable", IF(COUNTIF(AC!J18:J21,"NOT MET")>0,"NOT MET", IF(COUNTIF(AC!J18:J21,"MET")>0,"MET", ""))) -> MET | G7: 1 | H7: 3
A8: AC | B8: AC.L2-3.1.6 | C8: 2 | D8: Non-Privileged Account Use | E8: =IF(COUNTIF(AC!I22:I23,"Not Selected")>0,"Not Selected", IF(COUNTIF(AC!I22:I23,"Planned")>0,"Planned", IF(COUNTIF(AC!I22:I23,"Inherited")>0,"Inherited", IF(COUNTIF(AC!I22:I23,"Partially Implemented")>0,"Partially Implemented", IF(COUNTIF(AC!I22:I23,"Implemented")>0,"Implemented", ""))))) -> Implemented | F8: =IF(COUNTIF(AC!J22:J23,"Not Applicable")>0,"Not Applicable", IF(COUNTIF(AC!J22:J23,"NOT MET")>0,"NOT MET", IF(COUNTIF(AC!J22:J23,"MET")>0,"MET", ""))) -> MET | G8: 1 | H8: 1
A9: AC | B9: AC.L2-3.1.7 | C9: 2 | D9: Privileged Functions | E9: =IF(COUNTIF(AC!I24:I27,"Not Selected")>0,"Not Selected", IF(COUNTIF(AC!I24:I27,"Planned")>0,"Planned", IF(COUNTIF(AC!I24:I27,"Inherited")>0,"Inherited", IF(COUNTIF(AC!I24:I27,"Partially Implemented")>0,"Partially Implemented", IF(COUNTIF(AC!I24:I27,"Implemented")>0,"Implemented", ""))))) -> Implemented | F9: =IF(COUNTIF(AC!J24:J27,"Not Applicable")>0,"Not Applicable", IF(COUNTIF(AC!J24:J27,"NOT MET")>0,"NOT MET", IF(COUNTIF(AC!J24:J27,"MET")>0,"MET", ""))) -> MET | G9: 1 | H9: 1
A10: AC | B10: AC.L2-3.1.8 | C10: 2 | D10: Unsuccessful Logon Attempts | E10: =IF(COUNTIF(AC!I28:I29,"Not Selected")>0,"Not Selected", IF(COUNTIF(AC!I28:I29,"Planned")>0,"Planned", IF(COUNTIF(AC!I28:I29,"Inherited")>0,"Inherited", IF(COUNTIF(AC!I28:I29,"Partially Implemented")>0,"Partially Implemented", IF(COUNTIF(AC!I28:I29,"Implemented")>0,"Implemented", ""))))) -> Implemented | F10: =IF(COUNTIF(AC!J28:J29,"Not Applicable")>0,"Not Applicable", IF(COUNTIF(AC!J28:J29,"NOT MET")>0,"NOT MET", IF(COUNTIF(AC!J28:J29,"MET")>0,"MET", ""))) -> MET | G10: 1 | H10: 1
A11: AC | B11: AC.L2-3.1.9 | C11: 2 | D11: Privacy & Security Notices | E11: =IF(COUNTIF(AC!I31,"Not Selected")>0,"Not Selected", IF(COUNTIF(AC!I31,"Planned")>0,"Planned", IF(COUNTIF(AC!I31,"Inherited")>0,"Inherited", IF(COUNTIF(AC!I31,"Partially Implemented")>0,"Partially Implemented", IF(COUNTIF(AC!I31,"Implemented")>0,"Implemented", ""))))) -> Implemented | F11: =IF(COUNTIF(AC!J31,"Not Applicable")>0,"Not Applicable", IF(COUNTIF(AC!J31,"NOT MET")>0,"NOT MET", IF(COUNTIF(AC!J31,"MET")>0,"MET", ""))) -> MET | G11: 1 | H11: 1
A12: AC | B12: AC.L2-3.1.10 | C12: 2 | D12: Session Lock | E12: =IF(COUNTIF(AC!I32:I34,"Not Selected")>0,"Not Selected", IF(COUNTIF(AC!I32:I34,"Planned")>0,"Planned", IF(COUNTIF(AC!I32:I34,"Inherited")>0,"Inherited", IF(COUNTIF(AC!I32:I34,"Partially Implemented")>0,"Partially Implemented", IF(COUNTIF(AC!I32:I34,"Implemented")>0,"Implemented", ""))))) -> Implemented | F12: =IF(COUNTIF(AC!J32:J34,"Not Applicable")>0,"Not Applicable", IF(COUNTIF(AC!J32:J34,"NOT MET")>0,"NOT MET", IF(COUNTIF(AC!J32:J34,"MET")>0,"MET", ""))) -> MET | G12: 1 | H12: 1
A13: AC | B13: AC.L2-3.1.11 | C13: 2 | D13: Session Termination | E13: =IF(COUNTIF(AC!I35:I36,"Not Selected")>0,"Not Selected", IF(COUNTIF(AC!I35:I36,"Planned")>0,"Planned", IF(COUNTIF(AC!I35:I36,"Inherited")>0,"Inherited", IF(COUNTIF(AC!I35:I36,"Partially Implemented")>0,"Partially Implemented", IF(COUNTIF(AC!I35:I36,"Implemented")>0,"Implemented", ""))))) -> Implemented | F13: =IF(COUNTIF(AC!J35:J36,"Not Applicable")>0,"Not Applicable", IF(COUNTIF(AC!J35:J36,"NOT MET")>0,"NOT MET", IF(COUNTIF(AC!J35:J36,"MET")>0,"MET", ""))) -> MET | G13: 1 | H13: 1
A14: AC | B14: AC.L2-3.1.12 | C14: 2 | D14: Control Remote Access | E14: =IF(COUNTIF(AC!I40,"Not Selected")>0,"Not Selected", IF(COUNTIF(AC!I40,"Planned")>0,"Planned", IF(COUNTIF(AC!I40,"Inherited")>0,"Inherited", IF(COUNTIF(AC!I40,"Partially Implemented")>0,"Partially Implemented", IF(COUNTIF(AC!I40,"Implemented")>0,"Implemented", ""))))) -> Implemented | F14: =IF(COUNTIF(AC!J40,"Not Applicable")>0,"Not Applicable", IF(COUNTIF(AC!J40,"NOT MET")>0,"NOT MET", IF(COUNTIF(AC!J40,"MET")>0,"MET", ""))) -> MET | G14: 1 | H14: 5
A15: AC | B15: AC.L2-3.1.13 | C15: 2 | D15: Remote Access Confidentiality | E15: =IF(COUNTIF(AC!I41:I42,"Not Selected")>0,"Not Selected", IF(COUNTIF(AC!I41:I42,"Planned")>0,"Planned", IF(COUNTIF(AC!I41:I42,"Inherited")>0,"Inherited", IF(COUNTIF(AC!I41:I42,"Partially Implemented")>0,"Partially Implemented", IF(COUNTIF(AC!I41:I42,"Implemented")>0,"Implemented", ""))))) -> Implemented | F15: =IF(COUNTIF(AC!J41:J42,"Not Applicable")>0,"Not Applicable", IF(COUNTIF(AC!J41:J42,"NOT MET")>0,"NOT MET", IF(COUNTIF(AC!J41:J42,"MET")>0,"MET", ""))) -> MET | G15: 1 | H15: 5
A16: AC | B16: AC.L2-3.1.14 | C16: 2 | D16: Remote Access Routing | E16: =IF(COUNTIF(AC!I43:I44,"Not Selected")>0,"Not Selected", IF(COUNTIF(AC!I43:I44,"Planned")>0,"Planned", IF(COUNTIF(AC!I43:I44,"Inherited")>0,"Inherited", IF(COUNTIF(AC!I43:I44,"Partially Implemented")>0,"Partially Implemented", IF(COUNTIF(AC!I43:I44,"Implemented")>0,"Implemented", ""))))) -> Implemented | F16: =IF(COUNTIF(AC!J43:J44,"Not Applicable")>0,"Not Applicable", IF(COUNTIF(AC!J43:J44,"NOT MET")>0,"NOT MET", IF(COUNTIF(AC!J43:J44,"MET")>0,"MET", ""))) -> MET | G16: 1 | H16: 1
A17: AC | B17: AC.L2-3.1.15 | C17: 2 | D17: Privileged Remote Access | E17: =IF(COUNTIF(AC!I45:I48,"Not Selected")>0,"Not Selected", IF(COUNTIF(AC!I45:I48,"Planned")>0,"Planned", IF(COUNTIF(AC!I45:I48,"Inherited")>0,"Inherited", IF(COUNTIF(AC!I45:I48,"Partially Implemented")>0,"Partially Implemented", IF(COUNTIF(AC!I45:I48,"Implemented")>0,"Implemented", ""))))) -> Implemented | F17: =IF(COUNTIF(AC!J45:J48,"Not Applicable")>0,"Not Applicable", IF(COUNTIF(AC!J45:J48,"NOT MET")>0,"NOT MET", IF(COUNTIF(AC!J45:J48,"MET")>0,"MET", ""))) -> MET | G17: 1 | H17: 1
A18: AC | B18: AC.L2-3.1.16 | C18: 2 | D18: Wireless Access Authorization | E18: =IF(COUNTIF(AC!I49:I50,"Not Selected")>0,"Not Selected", IF(COUNTIF(AC!I49:I50,"Planned")>0,"Planned", IF(COUNTIF(AC!I49:I50,"Inherited")>0,"Inherited", IF(COUNTIF(AC!I49:I50,"Partially Implemented")>0,"Partially Implemented", IF(COUNTIF(AC!I49:I50,"Implemented")>0,"Implemented", ""))))) -> Inherited | F18: =IF(COUNTIF(AC!J49:J50,"Not Applicable")>0,"Not Applicable", IF(COUNTIF(AC!J49:J50,"NOT MET")>0,"NOT MET", IF(COUNTIF(AC!J49:J50,"MET")>0,"MET", ""))) -> MET | G18: 1 | H18: 5
A19: AC | B19: AC.L2-3.1.17 | C19: 2 | D19: Wireless Access Protection | E19: =IF(COUNTIF(AC!I52,"Not Selected")>0,"Not Selected", IF(COUNTIF(AC!I52,"Planned")>0,"Planned", IF(COUNTIF(AC!I52,"Inherited")>0,"Inherited", IF(COUNTIF(AC!I52,"Partially Implemented")>0,"Partially Implemented", IF(COUNTIF(AC!I52,"Implemented")>0,"Implemented", ""))))) -> Inherited | F19: =IF(COUNTIF(AC!J52,"Not Applicable")>0,"Not Applicable", IF(COUNTIF(AC!J52,"NOT MET")>0,"NOT MET", IF(COUNTIF(AC!J52,"MET")>0,"MET", ""))) -> MET | G19: 1 | H19: 5
A20: AC | B20: AC.L2-3.1.18 | C20: 2 | D20: Mobile Device Connection | E20: =IF(COUNTIF(AC!I55,"Not Selected")>0,"Not Selected", IF(COUNTIF(AC!I55,"Planned")>0,"Planned", IF(COUNTIF(AC!I55,"Inherited")>0,"Inherited", IF(COUNTIF(AC!I55,"Partially Implemented")>0,"Partially Implemented", IF(COUNTIF(AC!I55,"Implemented")>0,"Implemented", ""))))) -> Implemented | F20: =IF(COUNTIF(AC!J55,"Not Applicable")>0,"Not Applicable", IF(COUNTIF(AC!J55,"NOT MET")>0,"NOT MET", IF(COUNTIF(AC!J55,"MET")>0,"MET", ""))) -> MET | G20: 1 | H20: 5
A21: AC | B21: AC.L2-3.1.19 | C21: 2 | D21: Encrypt CUI on Mobile | E21: =IF(COUNTIF(AC!I56:I57,"Not Selected")>0,"Not Selected", IF(COUNTIF(AC!I56:I57,"Planned")>0,"Planned", IF(COUNTIF(AC!I56:I57,"Inherited")>0,"Inherited", IF(COUNTIF(AC!I56:I57,"Partially Implemented")>0,"Partially Implemented", IF(COUNTIF(AC!I56:I57,"Implemented")>0,"Implemented", ""))))) -> Implemented | F21: =IF(COUNTIF(AC!J56:J57,"Not Applicable")>0,"Not Applicable", IF(COUNTIF(AC!J56:J57,"NOT MET")>0,"NOT MET", IF(COUNTIF(AC!J56:J57,"MET")>0,"MET", ""))) -> MET | G21: 1 | H21: 3
A22: AC | B22: AC.L1-3.1.20 | C22: 1 | D22: External Connections | E22: =IF(COUNTIF(AC!I58:I63,"Not Selected")>0,"Not Selected", IF(COUNTIF(AC!I58:I63,"Planned")>0,"Planned", IF(COUNTIF(AC!I58:I63,"Inherited")>0,"Inherited", IF(COUNTIF(AC!I58:I63,"Partially Implemented")>0,"Partially Implemented", IF(COUNTIF(AC!I58:I63,"Implemented")>0,"Implemented", ""))))) -> Implemented | F22: =IF(COUNTIF(AC!J58:J63,"Not Applicable")>0,"Not Applicable", IF(COUNTIF(AC!J58:J63,"NOT MET")>0,"NOT MET", IF(COUNTIF(AC!J58:J63,"MET")>0,"MET", ""))) -> MET | G22: 1 | H22: 1
A23: AC | B23: AC.L2-3.1.21 | C23: 2 | D23: Portable Storage Use | E23: =IF(COUNTIF(AC!I64:I66,"Not Selected")>0,"Not Selected", IF(COUNTIF(AC!I64:I66,"Planned")>0,"Planned", IF(COUNTIF(AC!I64:I66,"Inherited")>0,"Inherited", IF(COUNTIF(AC!I64:I66,"Partially Implemented")>0,"Partially Implemented", IF(COUNTIF(AC!I64:I66,"Implemented")>0,"Implemented", ""))))) -> Implemented | F23: =IF(COUNTIF(AC!J64:J66,"Not Applicable")>0,"Not Applicable", IF(COUNTIF(AC!J64:J66,"NOT MET")>0,"NOT MET", IF(COUNTIF(AC!J64:J66,"MET")>0,"MET", ""))) -> MET | G23: 1 | H23: 1
A24: AC | B24: AC.L1-3.1.22 | C24: 1 | D24: Control Public Information | E24: =IF(COUNTIF(AC!I71,"Not Selected")>0,"Not Selected", IF(COUNTIF(AC!I71,"Planned")>0,"Planned", IF(COUNTIF(AC!I71,"Inherited")>0,"Inherited", IF(COUNTIF(AC!I71,"Partially Implemented")>0,"Partially Implemented", IF(COUNTIF(AC!I71,"Implemented")>0,"Implemented", ""))))) -> Implemented | F24: =IF(COUNTIF(AC!J71,"Not Applicable")>0,"Not Applicable", IF(COUNTIF(AC!J71,"NOT MET")>0,"NOT MET", IF(COUNTIF(AC!J71,"MET")>0,"MET", ""))) -> MET | G24: 1 | H24: 1
D25: Awareness and Training (AT)
A26: AT | B26: AT.L2-3.2.1 | C26: 2 | D26: Role-Based Risk Awareness | E26: =IF(COUNTIF(AT!I2:I5,"Not Selected")>0,"Not Selected", IF(COUNTIF(AT!I2:I5,"Planned")>0,"Planned", IF(COUNTIF(AT!I2:I5,"Inherited")>0,"Inherited", IF(COUNTIF(AT!I2:I5,"Partially Implemented")>0,"Partially Implemented", IF(COUNTIF(AT!I2:I5,"Implemented")>0,"Implemented", ""))))) -> Implemented | F26: =IF(COUNTIF(AT!J2:J5,"Not Applicable")>0,"Not Applicable", IF(COUNTIF(AT!J2:J5,"NOT MET")>0,"NOT MET", IF(COUNTIF(AT!J2:J5,"Partially MET")>0,"Partially MET", IF(COUNTIF(AT!J2:J5,"MET")>0,"MET", "")))) -> MET | G26: 1 | H26: 5
A27: AT | B27: AT.L2-3.2.2 | C27: 2 | D27: Role-Based Training | E27: =IF(COUNTIF(AT!I6:I8,"Not Selected")>0,"Not Selected", IF(COUNTIF(AT!I6:I8,"Planned")>0,"Planned", IF(COUNTIF(AT!I6:I8,"Inherited")>0,"Inherited", IF(COUNTIF(AT!I6:I8,"Partially Implemented")>0,"Partially Implemented", IF(COUNTIF(AT!I6:I8,"Implemented")>0,"Implemented", ""))))) -> Implemented | F27: =IF(COUNTIF(AT!J6:J8,"Not Applicable")>0,"Not Applicable", IF(COUNTIF(AT!J6:J8,"NOT MET")>0,"NOT MET", IF(COUNTIF(AT!J6:J8,"Partially MET")>0,"Partially MET", IF(COUNTIF(AT!J6:J8,"MET")>0,"MET", "")))) -> MET | G27: 1 | H27: 5
A28: AT | B28: AT.L2-3.2.3 | C28: 2 | D28: Insider Threat Awareness | E28: =IF(COUNTIF(AT!I9:I10,"Not Selected")>0,"Not Selected", IF(COUNTIF(AT!I9:I10,"Planned")>0,"Planned", IF(COUNTIF(AT!I9:I10,"Inherited")>0,"Inherited", IF(COUNTIF(AT!I9:I10,"Partially Implemented")>0,"Partially Implemented", IF(COUNTIF(AT!I9:I10,"Implemented")>0,"Implemented", ""))))) -> Implemented | F28: =IF(COUNTIF(AT!J9:J10,"Not Applicable")>0,"Not Applicable", IF(COUNTIF(AT!J9:J10,"NOT MET")>0,"NOT MET", IF(COUNTIF(AT!J9:J10,"Partially MET")>0,"Partially MET", IF(COUNTIF(AT!J9:J10,"MET")>0,"MET", "")))) -> MET | G28: 1 | H28: 1
D29: Audit and Accountability (AU)
A30: AU | B30: AU.L2-3.3.1 | C30: 2 | D30: System Auditing | E30: =IF(COUNTIF(AU!I2:I7,"Not Selected")>0,"Not Selected", IF(COUNTIF(AU!I2:I7,"Planned")>0,"Planned", IF(COUNTIF(AU!I2:I7,"Inherited")>0,"Inherited", IF(COUNTIF(AU!I2:I7,"Partially Implemented")>0,"Partially Implemented", IF(COUNTIF(AU!I2:I7,"Implemented")>0,"Implemented", ""))))) -> Implemented | F30: =IF(COUNTIF(AU!J2:J7,"Not Applicable")>0,"Not Applicable", IF(COUNTIF(AU!J2:J7,"NOT MET")>0,"NOT MET", IF(COUNTIF(AU!J2:J7,"Partially MET")>0,"Partially MET", IF(COUNTIF(AU!J2:J7,"MET")>0,"MET", "")))) -> MET | G30: 1 | H30: 5
A31: AU | B31: AU.L2-3.3.2 | C31: 2 | D31: User Accountability | E31: =IF(COUNTIF(AU!I8:I9,"Not Selected")>0,"Not Selected", IF(COUNTIF(AU!I8:I9,"Planned")>0,"Planned", IF(COUNTIF(AU!I8:I9,"Inherited")>0,"Inherited", IF(COUNTIF(AU!I8:I9,"Partially Implemented")>0,"Partially Implemented", IF(COUNTIF(AU!I8:I9,"Implemented")>0,"Implemented", ""))))) -> Implemented | F31: =IF(COUNTIF(AU!J8:J9,"Not Applicable")>0,"Not Applicable", IF(COUNTIF(AU!J8:J9,"NOT MET")>0,"NOT MET", IF(COUNTIF(AU!J8:J9,"Partially MET")>0,"Partially MET", IF(COUNTIF(AU!J8:J9,"MET")>0,"MET", "")))) -> MET | G31: 1 | H31: 3
A32: AU | B32: AU.L2-3.3.3 | C32: 2 | D32: Event Review | E32: =IF(COUNTIF(AU!I10:I12,"Not Selected")>0,"Not Selected", IF(COUNTIF(AU!I10:I12,"Planned")>0,"Planned", IF(COUNTIF(AU!I10:I12,"Inherited")>0,"Inherited", IF(COUNTIF(AU!I10:I12,"Partially Implemented")>0,"Partially Implemented", IF(COUNTIF(AU!I10:I12,"Implemented")>0,"Implemented", ""))))) -> Implemented | F32: =IF(COUNTIF(AU!J10:J12,"Not Applicable")>0,"Not Applicable", IF(COUNTIF(AU!J10:J12,"NOT MET")>0,"NOT MET", IF(COUNTIF(AU!J10:J12,"Partially MET")>0,"Partially MET", IF(COUNTIF(AU!J10:J12,"MET")>0,"MET", "")))) -> MET | G32: 1 | H32: 1
A33: AU | B33: AU.L2-3.3.4 | C33: 2 | D33: Audit Failure Alerting | E33: =IF(COUNTIF(AU!I13:I15,"Not Selected")>0,"Not Selected", IF(COUNTIF(AU!I13:I15,"Planned")>0,"Planned", IF(COUNTIF(AU!I13:I15,"Inherited")>0,"Inherited", IF(COUNTIF(AU!I13:I15,"Partially Implemented")>0,"Partially Implemented", IF(COUNTIF(AU!I13:I15,"Implemented")>0,"Implemented", ""))))) -> Implemented | F33: =IF(COUNTIF(AU!J13:J15,"Not Applicable")>0,"Not Applicable", IF(COUNTIF(AU!J13:J15,"NOT MET")>0,"NOT MET", IF(COUNTIF(AU!J13:J15,"Partially MET")>0,"Partially MET", IF(COUNTIF(AU!J13:J15,"MET")>0,"MET", "")))) -> MET | G33: 1 | H33: 1
A34: AU | B34: AU.L2-3.3.5 | C34: 2 | D34: Audit Correlation | E34: =IF(COUNTIF(AU!I16:I17,"Not Selected")>0,"Not Selected", IF(COUNTIF(AU!I16:I17,"Planned")>0,"Planned", IF(COUNTIF(AU!I16:I17,"Inherited")>0,"Inherited", IF(COUNTIF(AU!I16:I17,"Partially Implemented")>0,"Partially Implemented", IF(COUNTIF(AU!I16:I17,"Implemented")>0,"Implemented", ""))))) -> Implemented | F34: =IF(COUNTIF(AU!J16:J17,"Not Applicable")>0,"Not Applicable", IF(COUNTIF(AU!J16:J17,"NOT MET")>0,"NOT MET", IF(COUNTIF(AU!J16:J17,"Partially MET")>0,"Partially MET", IF(COUNTIF(AU!J16:J17,"MET")>0,"MET", "")))) -> MET | G34: 1 | H34: 5
A35: AU | B35: AU.L2-3.3.6 | C35: 2 | D35: Reduction & Reporting | E35: =IF(COUNTIF(AU!I18:I19,"Not Selected")>0,"Not Selected", IF(COUNTIF(AU!I18:I19,"Planned")>0,"Planned", IF(COUNTIF(AU!I18:I19,"Inherited")>0,"Inherited", IF(COUNTIF(AU!I18:I19,"Partially Implemented")>0,"Partially Implemented", IF(COUNTIF(AU!I18:I19,"Implemented")>0,"Implemented", ""))))) -> Implemented | F35: =IF(COUNTIF(AU!J18:J19,"Not Applicable")>0,"Not Applicable", IF(COUNTIF(AU!J18:J19,"NOT MET")>0,"NOT MET", IF(COUNTIF(AU!J18:J19,"Partially MET")>0,"Partially MET", IF(COUNTIF(AU!J18:J19,"MET")>0,"MET", "")))) -> MET | G35: 1 | H35: 1
A36: AU | B36: AU.L2-3.3.7 | C36: 2 | D36: Authoritative Time Source | E36: =IF(COUNTIF(AU!I20:I22,"Not Selected")>0,"Not Selected", IF(COUNTIF(AU!I20:I22,"Planned")>0,"Planned", IF(COUNTIF(AU!I20:I22,"Inherited")>0,"Inherited", IF(COUNTIF(AU!I20:I22,"Partially Implemented")>0,"Partially Implemented", IF(COUNTIF(AU!I20:I22,"Implemented")>0,"Implemented", ""))))) -> Implemented | F36: =IF(COUNTIF(AU!J20:J22,"Not Applicable")>0,"Not Applicable", IF(COUNTIF(AU!J20:J22,"NOT MET")>0,"NOT MET", IF(COUNTIF(AU!J20:J22,"Partially MET")>0,"Partially MET", IF(COUNTIF(AU!J20:J22,"MET")>0,"MET", "")))) -> MET | G36: 1 | H36: 1
A37: AU | B37: AU.L2-3.3.8 | C37: 2 | D37: Audit Protection | E37: =IF(COUNTIF(AU!I23:I28,"Not Selected")>0,"Not Selected", IF(COUNTIF(AU!I23:I28,"Planned")>0,"Planned", IF(COUNTIF(AU!I23:I28,"Inherited")>0,"Inherited", IF(COUNTIF(AU!I23:I28,"Partially Implemented")>0,"Partially Implemented", IF(COUNTIF(AU!I23:I28,"Implemented")>0,"Implemented", ""))))) -> Implemented | F37: =IF(COUNTIF(AU!J23:J28,"Not Applicable")>0,"Not Applicable", IF(COUNTIF(AU!J23:J28,"NOT MET")>0,"NOT MET", IF(COUNTIF(AU!J23:J28,"Partially MET")>0,"Partially MET", IF(COUNTIF(AU!J23:J28,"MET")>0,"MET", "")))) -> MET | G37: 1 | H37: 1
A38: AU | B38: AU.L2-3.3.9 | C38: 2 | D38: Audit Management | E38: =IF(COUNTIF(AU!I30,"Not Selected")>0,"Not Selected", IF(COUNTIF(AU!I30,"Planned")>0,"Planned", IF(COUNTIF(AU!I30,"Inherited")>0,"Inherited", IF(COUNTIF(AU!I30,"Partially Implemented")>0,"Partially Implemented", IF(COUNTIF(AU!I30,"Implemented")>0,"Implemented", ""))))) -> Implemented | F38: =IF(COUNTIF(AU!J30,"Not Applicable")>0,"Not Applicable", IF(COUNTIF(AU!J30,"NOT MET")>0,"NOT MET", IF(COUNTIF(AU!J30,"Partially MET")>0,"Partially MET", IF(COUNTIF(AU!J30,"MET")>0,"MET", "")))) -> MET | G38: 1 | H38: 1
D39: Security Assessment (CA)
A40: CA | B40: CA.L2-3.12.1 | C40: 2 | D40: Security Control Assessment | E40: =IF(COUNTIF(CA!I2:I3,"Not Selected")>0,"Not Selected", IF(COUNTIF(CA!I2:I3,"Planned")>0,"Planned", IF(COUNTIF(CA!I2:I3,"Inherited")>0,"Inherited", IF(COUNTIF(CA!I2:I3,"Partially Implemented")>0,"Partially Implemented", IF(COUNTIF(CA!I2:I3,"Implemented")>0,"Implemented", ""))))) -> Implemented | F40: =IF(COUNTIF(CA!J2:J3,"Not Applicable")>0,"Not Applicable", IF(COUNTIF(CA!J2:J3,"NOT MET")>0,"NOT MET", IF(COUNTIF(CA!J2:J3,"Partially MET")>0,"Partially MET", IF(COUNTIF(CA!J2:J3,"MET")>0,"MET", "")))) -> MET | G40: 1 | H40: 5
...

Sheet AC
A1: Practice Name | B1: Practice ID | C1: Procedure ID | D1: Assessment Objective/Determine if: | E1: EXAMINE | F1: INTERVIEW | G1: TEST | H1: Observation Statement | I1: Implementation Status | J1: Assessment Result | K1: Evidence/Artifacts
A2: Authorized Access Control | B2: AC.L1-3.1.1 | C2: 3.1.1 [a] | D2: authorized users are identified. | E2: Examine: [SELECT FROM: Access control policy; procedures addressing account management; system security plan; system design documentation; system configuration settings and associated documentation; list of active system accounts and the name of the individual associated with each account; notifications or records of recently transferred, separated, or terminated employees; list of conditions for group and role membership; list of recently disabled system accounts along with the name of the individual associated with each account; access authorization records; account management compliance reviews; system monitoring records; system audit logs and records; list of devices and systems authorized to connect to organizational systems; other relevant documents or records]. | F2: Interview: [SELECT FROM: Personnel with account management responsibilities; system or network administrators; personnel with information security responsibilities]. | G2: Test: [SELECT FROM: Organizational processes for managing system accounts; mechanisms for implementing account management]. | H2: 11/06/2025: Assurit Cyber Handbook defines the company's requirement for uniquely identifying users, processes, and devices. Users are identified via their unique MS Entra ID account which is provisioned and assigned by Assurit. A unique local AVD admin account is assigned to the company's System Administrator (assurit-bg). | I2: Implemented | J2: MET | K2: APIS_SSP_v1.1-10-31-2025.docx Assurit_Cyber_Handbook_v2.1-09-08-2025.docx AC.L1-3.1.1a-11-06-2025.png
B3: AC.L1-3.1.1 | C3: 3.1.1 [b] | D3: processes acting on behalf of authorized users are identified. | H3: 11/06/2025: Service groups/accounts are uniquely identified by their group name and/or UPN. | I3: Implemented | J3: MET | K3: APIS_SSP_v1.1-10-31-2025.docx AC.L1-3.1.1b1-11-06-2025.png AC.L1-3.1.1b2-11-06-2025.png
B4: AC.L1-3.1.1 | C4: 3.1.1 [c] | D4: devices (and other systems) authorized to connect to the system are identified. | H4: 11/06/2025: AVD are assigned a unique hostname and primary user. | I4: Implemented | J4: MET | K4: APIS_SSP_v1.1-10-31-2025.docx AC.L1-3.1.1c1-11-06-2025.png AC.L1-3.1.1c2-11-06-2025.png
B5: AC.L1-3.1.1 | C5: 3.1.1 [d] | D5: system access is limited to authorized users. | H5: 11/06/2025: APIS Admin Portals are restricted to select authorized users. M365 services and AVD is restricted to authorized users and groups only. This is configured through conditional access policies. | I5: Implemented | J5: MET | K5: APIS_SSP_v1.1-10-31-2025.docx AC.L1-3.1.1d1-11-06-2025.png AC.L1-3.1.1d2-11-06-2025.png
B6: AC.L1-3.1.1 | C6: 3.1.1 [e] | D6: system access is limited to processes acting on behalf of authorized users. | H6: 11/06/2025: Access to service groups/accounts are restricted to authorized users only. | I6: Implemented | J6: MET | K6: APIS_SSP_v1.1-10-31-2025.docx AC.L1-3.1.1e-11-06-2025.png
B7: AC.L1-3.1.1 | C7: 3.1.1 [f] | D7: system access is limited to authorized devices (including other systems). | H7: 11/06/2025: Access to APIS AVD is restricted to authorized users and trusted locations only configured through Azure conditional access policies. | I7: Implemented | J7: MET | K7: APIS_SSP_v1.1-10-31-2025.docx AC.L1-3.1.1f1-11-06-2025.png AC.L1-3.1.1f2-11-06-2025.png
A8: Transaction & Function Control | B8: AC.L1-3.1.2 | C8: 3.1.2 [a] | D8: the types of transactions and functions that authorized users are permitted to execute are defined. | E8: Examine: [SELECT FROM: Access control policy; procedures addressing access enforcement; system security plan; system design documentation; list of approved authorizations including remote access authorizations; system audit logs and records; system configuration settings and associated documentation; other relevant documents or records]. | F8: Interview: [SELECT FROM: Personnel with access enforcement responsibilities; system or network administrators; personnel with information security responsibilities; system developers]. | G8: Test: [SELECT FROM: Mechanisms implementing access control policy]. | H8: 11/06/2025: Assurit Cyber Handbook defines the company's requirement for authorized system functions and acceptable use. The SSP defines M365 services and Administrative Consoles/Portals as authorized functions. | I8: Implemented | J8: MET | K8: APIS_SSP_v1.1-10-31-2025.docx Assurit_Cyber_Handbook_v2.1-09-08-2025.docx
B9: AC.L1-3.1.2 | C9: 3.1.2 [b] | D9: system access is limited to the defined types of transactions and functions for authorized users. | H9: 11/06/2025: Access to defined functions are restricted by Azure groups and conditional access policies. | I9: Implemented | J9: MET | K9: APIS_SSP_v1.1-10-31-2025.docx AC.L1-3.1.2b-11-06-2025.png
A10: Control CUI Flow | B10: AC.L2-3.1.3 | C10: 3.1.3 [a] | D10: information flow control policies are defined. | E10: Examine: [SELECT FROM: Access control policy; information flow control policies; procedures addressing information flow enforcement; system security plan; system design documentation; system configuration settings and associated documentation; list of information flow authorizations; system baseline configuration; system audit logs and records; other relevant documents or records]. | F10: Interview: [SELECT FROM: System or network administrators; personnel with information security responsibilities; system developers]. | G10: Test: [SELECT FROM: Mechanisms implementing information flow enforcement policy]. | H10: 11/06/2025: Assurit Cyber Handbook defines the company's CUI Information Flow policy and requirements. | I10: Implemented | J10: MET | K10: APIS_SSP_v1.1-10-31-2025.docx Assurit_Cyber_Handbook_v2.1-09-08-2025.docx
B11: AC.L2-3.1.3 | C11: 3.1.3 [b] | D11: methods and enforcement mechanisms for controlling the flow of CUI are defined. | H11: 11/06/2025: SSP defines GCC High M365 services (OneDrive, Exchange, SharePoint) for storing, processing, and or transmitting CUI data. In addition, Assurit's M365 services can only be accessed from AVD and whitelist locations. | I11: Implemented | J11: MET | K11: APIS_SSP_v1.1-10-31-2025.docx
B12: AC.L2-3.1.3 | C12: 3.1.3 [c] | D12: designated sources and destinations (e.g., networks, individuals, and devices) for CUI within the system and between interconnected systems are identified. | H12: 11/06/2025: SSP defines GCC High M365 services (OneDrive, Exchange, SharePoint) for storing, processing, and or transmitting CUI data. In addition, Assurit's M365 services can only be accessed from AVD and whitelist locations. | I12: Implemented | J12: MET | K12: APIS_SSP_v1.1-10-31-2025.docx
B13: AC.L2-3.1.3 | C13: 3.1.3 [d] | D13: authorizations for controlling the flow of CUI are defined. | H13: 11/06/2025: Authorizations for controlling CUI flow is defined for ingress/egress into Assurit's M365 services which can only be access from APIS AVDs. Purview policies are enabled to provide sensitivity labels for incoming messages. Exchange rules are enabled to ensure that all outgoing email must be approved by an Assurit System Administrator before sending. | I13: Implemented | J13: MET | K13: APIS_SSP_v1.1-10-31-2025.docx AC.L1-3.1.3d1-11-06-2025.png AC.L1-3.1.3d2-11-06-2025.png AC.L1-3.1.3d3-11-06-2025.png AC.L1-3.1.3d4-11-06-2025.png AC.L1-3.1.3d5-11-06-2025.png
B14: AC.L2-3.1.3 | C14: 3.1.3 [e] | D14: approved authorizations for controlling the flow of CUI are enforced. | H14: 11/06/2025: Purview policies are enabled to provide sensitivity labels for incoming messages and attachments. Exchange rules are enabled to ensure that all outgoing email must be approved by an Assurit System Administrator before sending. | I14: Implemented | J14: MET | K14: APIS_SSP_v1.1-10-31-2025.docx AC.L1-3.1.3d1-11-06-2025.png AC.L1-3.1.3d2-11-06-2025.png AC.L1-3.1.3d3-11-06-2025.png AC.L1-3.1.3d4-11-06-2025.png AC.L1-3.1.3d5-11-06-2025.png
A15: Separation of Duties | B15: AC.L2-3.1.4 | C15: 3.1.4 [a] | D15: the duties of individuals requiring separation are defined. | E15: Examine: [SELECT FROM: Access control policy; procedures addressing divisions of responsibility and separation of duties; system security plan; system configuration settings and associated documentation; list of divisions of responsibility and separation of duties; system access authorizations; system audit logs and records; other relevant documents or records]. | F15: Interview: [SELECT FROM: Personnel with responsibilities for defining divisions of responsibility and separation of duties; personnel with information security responsibilities; system or network administrators]. | G15: Test: [SELECT FROM: Mechanisms implementing separation of duties policy]. | H15: 11/06/2025: APIS roles and responsibilities are defined within the Assurit Cyber Handbook. Each role requiring separate responsibilities are thoroughly described and highlights any security-related responsibilities as it pertains to APIS and CUI. | I15: Implemented | J15: MET | K15: APIS_SSP_v1.1-10-31-2025.docx Assurit_Cyber_Handbook_v2.1-09-08-2025.docx
B16: AC.L2-3.1.4 | C16: 3.1.4 [b] | D16: responsibilities for duties that require separation are assigned to separate individuals. | H16: 11/06/2025: Assurit designates an Authorizing Official, System Owner, and System Administrator for APIS. Role designations and contact information are documented for each assigned role within the SSP. | I16: Implemented | J16: MET | K16: APIS_SSP_v1.1-10-31-2025.docx
B17: AC.L2-3.1.4 | C17: 3.1.4 [c] | D17: access privileges that enable individuals to exercise the duties that require separation are granted to separate individuals. | H17: 11/06/2025: Assurit assigns access privileges based on the user's APIS roles which are divided into 3 groups: -APIS-Admins (Privileged) -APIS-Users (Non-Privileged) -APIS Secure (SharePoint/OneDrive) Access/permissions are assigned for each group for APIS resources through conditional access policies and direct assignments. | I17: Implemented | J17: MET | K17: APIS_SSP_v1.1-10-31-2025.docx AC.L2-3.1.4c1-11-06-2025.png AC.L2-3.1.4c2-11-06-2025.png AC.L2-3.1.4c3-11-06-2025.png AC.L2-3.1.4c4-11-06-2025.png AC.L2-3.1.4c5-11-06-2025.png AC.L2-3.1.4c6-11-06-2025.png AC.L2-3.1.4c7-11-06-2025.png AC.L2-3.1.4c8-11-06-2025.png AC.L2-3.1.4c9-11-06-2025.png
A18: Least Privilege | B18: AC.L2-3.1.5 | C18: 3.1.5 [a] | D18: privileged accounts are identified. | E18: Examine: [SELECT FROM: Access control policy; procedures addressing account management; system security plan; system design documentation; system configuration settings and associated documentation; list of active system accounts and the name of the individual associated with each account; list of conditions for group and role membership; notifications or records of recently transferred, separated, or terminated employees; list of recently disabled system accounts along with the name of the individual associated with each account; access authorization records; account management compliance reviews; system monitoring/audit records; procedures addressing least privilege; list of security functions (deployed in hardware, software, and firmware) and security-relevant information for which access is to be explicitly authorized; list of system-generated privileged accounts; list of system administration personnel; other relevant documents or records]. | F18: Interview: [SELECT FROM: Personnel with account management responsibilities; system or network administrators; personnel with information security responsibilities; personnel with responsibilities for defining least privileges necessary to accomplish specified tasks]. | G18: Test: [SELECT FROM: Organizational processes for managing system accounts; mechanisms for implementing account management; mechanisms implementing least privilege functions; mechanisms prohibiting privileged access to the system]. | H18: 11/06/2025: Privileged groups, accounts, and purposes are defined within the SSP. | I18: Implemented | J18: MET | K18: APIS_SSP_v1.1-10-31-2025.docx Assurit_Cyber_Handbook_v2.1-09-08-2025.docx
B19: AC.L2-3.1.5 | C19: 3.1.5 [b] | D19: access to privileged accounts is authorized in accordance with the principle of least privilege. | H19: 11/06/2025: Provisioning and access to privileged accounts are authorized by Assurit's Authorizing Official and System Owner. | I19: Implemented | J19: MET | K19: APIS_SSP_v1.1-10-31-2025.docx Assurit_Cyber_Handbook_v2.1-09-08-2025.docx
B20: AC.L2-3.1.5 | C20: 3.1.5 [c] | D20: security functions are identified. | H20: 11/6/2025: Security-related functionality for APIS is defined within the SSP as environment configurations, virtual machine configurations, and M365 settings. | I20: Implemented | J20: MET | K20: APIS_SSP_v1.1-10-31-2025.docx Assurit_Cyber_Handbook_v2.1-09-08-2025.docx
B21: AC.L2-3.1.5 | C21: 3.1.5 [d] | D21: access to security functions is authorized in accordance with the principle of least privilege. | H21: 11/06/2025: Provisioning and access to security functions are authorized by Assurit's Authorizing Official and System Owner. | I21: Implemented | J21: MET | K21: APIS_SSP_v1.1-10-31-2025.docx Assurit_Cyber_Handbook_v2.1-09-08-2025.docx
A22: Non-Privileged Account Use | B22: AC.L2-3.1.6 | C22: 3.1.6 [a] | D22: nonsecurity functions are identified. | E22: [SELECT FROM: Access control policy; procedures addressing least privilege; system security plan; list of system-generated security functions assigned to system accounts or roles; system configuration settings and associated documentation; system audit logs and records; other relevant documents or records]. | F22: Interview: [SELECT FROM: Personnel with responsibilities for defining least privileges necessary to accomplish specified organizational tasks; personnel with information security responsibilities; system or network administrators]. | G22: Test: [SELECT FROM: Mechanisms implementing least privilege functions]. | H22: 11/28/2025: Nonsecurity functions are identified as conventional, non-configuration usage of O365 and Azure services. | I22: Implemented | J22: MET | K22: APIS_SSP_v1.1-10-31-2025.docx Assurit_Cyber_Handbook_v2.1-09-08-2025.docx
B23: AC.L2-3.1.6 | C23: 3.1.6 [b] | D23: users are required to use non-privileged accounts or roles when accessing nonsecurity functions. | H23: 11/28/2025: APIS users can only access O365 services using their Entra ID account. The APIS O365 services can only be accessed from the APIS network. Although non-privileged, O365 services are required for both privileged and non-privileged users (word, excel, sharepoint, etc) to perform their duties. | I23: Implemented | J23: MET | K23: APIS_SSP_v1.1-10-31-2025.docx AC.L2-3.1.6b1-12-10-2025.png AC.L2-3.1.6b2-12-10-2025.png
A24: Privileged Functions | B24: AC.L2-3.1.7 | C24: 3.1.7 [a] | D24: privileged functions are defined. | E24: Examine: [SELECT FROM: Access control policy; procedures addressing least privilege; system security plan; system design documentation; list of privileged functions and associated user account assignments; system configuration settings and associated documentation; system audit logs and records; other relevant documents or records]. | F24: Interview: [SELECT FROM: Personnel with responsibilities for defining least privileges necessary to accomplish specified tasks; personnel with information security responsibilities; system developers]. | G24: Test: [SELECT FROM: Mechanisms implementing least privilege functions for non-privileged users; mechanisms auditing the execution of privileged functions]. | H24: 12/10/2025: Privileged functions are defined within the SSP which include: o Azure environment configurations o Virtual machine configurations o Exchange, SharePoint, OneDrive Settings | I24: Implemented | J24: MET | K24: APIS_SSP_v1.1-10-31-2025.docx
B25: AC.L2-3.1.7 | C25: 3.1.7 [b] | D25: non-privileged users are defined. | H25: 12/10/2025: Non-privileged users are conventional system users and are assigned the APIS-Users group. | I25: Implemented | J25: MET | K25: AC.L2-3.1.7b1-12-10-2025.png
B26: AC.L2-3.1.7 | C26: 3.1.7 [c] | D26: non-privileged users are prevented from executing privileged functions. | H26: 12/10/2025: Non-privileged users are prevented from conditional access policies and AVD/Intune policies. Non-privileged users are restricted by CA policies from logging into Admin portals. AVD IAM roles are assigned to specific users which only allow for non-privileged logins (Virtual Machine User Login). Intune policies apply DISA STIG (Microsoft Windows 11 STIG - Ver 2, Rel 5) which restricts privileged actions and requires elevated authentication. | I26: Implemented | J26: MET | K26: AC.L2-3.1.7c1-12-10-2025.png AC.L2-3.1.7c2-12-10-2025.png AC.L2-3.1.7c3-12-10-2025.png
B27: AC.L2-3.1.7 | C27: 3.1.7 [d] | D27: the execution of privileged functions is captured in audit logs. | H27: 12/10/2025: The execution of privlieged functions are captured within several sources that include Azure audit logs and sign-in logs which tracks any changes made to the admin consoles. AVD logs are captured and forwarded to sentinel for monitoring. | I27: Implemented | J27: MET | K27: AC.L2-3.1.7d1-12-10-2025.png AC.L2-3.1.7d2-12-10-2025.png
A28: Unsuccessful Logon Attempts | B28: AC.L2-3.1.8 | C28: 3.1.8 [a] | D28: the means of limiting unsuccessful logon attempts is defined. | E28: Examine: [SELECT FROM: Access control policy; procedures addressing unsuccessful logon attempts; system security plan; system design documentation; system configuration settings and associated documentation; system audit logs and records; other relevant documents or records]. | F28: Interview: [SELECT FROM: Personnel with information security responsibilities; system developers; system or network administrators]. | G28: Test: [SELECT FROM: Mechanisms implementing access control policy for unsuccessful logon attempts]. | H28: 12/10/2025: Assurit's unsuccessful login threshold is defined as (3) consecutive failed attempts. After the 3rd attempt, users are blocked from attempting login for 15 minutes (900 seconds). The means for preventing this is configured through Entra ID Authentication Method settings and Intune policies. | I28: Implemented | J28: MET | K28: APIS_SSP_v1.1-10-31-2025.docx Assurit_Cyber_Handbook_v2.1-09-08-2025.docx
B29: AC.L2-3.1.8 | C29: 3.1.8 [b] | D29: the defined means of limiting unsuccessful logon attempts is implemented. | H29: 12/10/2025: Entra ID services are implemented to apply the company's lockout thresholds, and reinforced through intune policies (AVD). All APIS services are integrated with Entra ID to ensure a uniformed authentication scheme. | I29: Implemented | J29: MET | K29: AC.L2-3.1.8b1-12-10-2025.png
A30: Privacy & Security Notices | B30: AC.L2-3.1.9 | C30: 3.1.9 [a] | D30: privacy and security notices required by CUI-specified rules are identified, consistent, and associated with the specific CUI category. | E30: Examine: [SELECT FROM: Privacy and security policies, procedures addressing system use notification; documented approval of system use notification messages or banners; system audit logs and records; system design documentation; user acknowledgements of notification message or banner; system security plan; system use notification messages; system configuration settings and associated documentation; other relevant documents or records]. | F30: Interview: [SELECT FROM: System or network administrators; personnel with information security responsibilities; personnel with responsibility for providing legal advice; system developers]. | G30: Test: [SELECT FROM: Mechanisms implementing system use notification]. | H30: 12/10/2025: Assurit defines a security/privacy notice that is consistent with the company's CUI requirements within the SSP and Cyber Handbook. | I30: Implemented | J30: MET | K30: APIS_SSP_v1.1-10-31-2025.docx Assurit_Cyber_Handbook_v2.1-09-08-2025.docx
B31: AC.L2-3.1.9 | C31: 3.1.9 [b] | D31: privacy and security notices are displayed. | H31: 12/10/2025: The notice is displayed to all users that login to AVD that require acknowledgement prior to access: The Assurit Protected Information System is for authorized use only. This system may contain Controlled Unclassified Information (CUI) and Federal Contract Information (FCI). All users are required to handle, safeguard, and protect such information in accordance with applicable laws, regulations, and contractual requirements. By accessing or using this system, you acknowledge and consent to monitoring, recording, and auditing of all activities for security, compliance, and operational purposes. Unauthorized access, use, or modification of this system is strictly prohibited and may result in disciplinary action, civil penalties, and/or criminal prosecution. All data transmitted, processed, or stored on this system may be monitored and disclosed to authorized personnel or law enforcement as permitted by law. By proceeding, you confirm your understanding of these requirements and acknowledge you have no reasonable expectation of privacy while using this system. | I31: Implemented | J31: MET | K31: AC.L2-3.1.9b1-12-10-2025.png
A32: Session Lock | B32: AC.L2-3.1.10 | C32: 3.1.10 [a] | D32: the period of inactivity after which the system initiates a session lock is defined. | E32: Examine: [SELECT FROM: Access control policy; procedures addressing session lock; procedures addressing identification and authentication; system design documentation; system configuration settings and associated documentation; system security plan; other relevant documents or records]. | F32: Interview: [SELECT FROM: System or network administrators; personnel with information security responsibilities; system developers]. | G32: Test: [SELECT FROM: Mechanisms implementing access control policy for session lock]. | H32: 12/10/2025: Assurit defines session lock requirements within the Cyber handbook. The policy requirement states that system initiated session locks should occur after 15 minutes of inactivity. | I32: Implemented | J32: MET | K32: APIS_SSP_v1.1-10-31-2025.docx Assurit_Cyber_Handbook_v2.1-09-08-2025.docx
B33: AC.L2-3.1.10 | C33: 3.1.10 [b] | D33: access to the system and viewing of data is prevented by initiating a session lock after the defined period of inactivity. | H33: 12/10/2025: System and user initiated session lock terminates AVD RDP sessions, preventing further access to the environment until re-authentication. | I33: Implemented | J33: MET | K33: AC.L2-3.1.10b1-12-10-2025.png AC.L2-3.1.10b2-12-10-2025.png
B34: AC.L2-3.1.10 | C34: 3.1.10 [c] | D34: previously visible information is concealed via a pattern-hiding display after the defined period of inactivity. | H34: 12/10/2025: System and user initiated session lock terminates AVD RDP sessions, preventing further access to the environment until re-authentication. This is concealed by a black screen and logout message. | I34: Implemented | J34: MET | K34: AC.L2-3.1.10b1-12-10-2025.png AC.L2-3.1.10b2-12-10-2025.png
A35: Session Termination | B35: AC.L2-3.1.11 | C35: 3.1.11 [a] | D35: conditions requiring a user session to terminate are defined. | E35: Examine: [SELECT FROM: Access control policy; procedures addressing session termination; system design documentation; system security plan; system configuration settings and associated documentation; list of conditions or trigger events requiring session disconnect; system audit logs and records; other relevant documents or records]. | F35: Interview: [SELECT FROM: System or network administrators; personnel with information security responsibilities; system developers]. | G35: Test: [SELECT FROM: Mechanisms implementing user session termination]. | H35: 12/10/2025: Assurit defines the conditions for session termination within the Cyber handbook. Termination conditions include exceeding a 15 minute inactivity period or a user-initiated logoff. | I35: Implemented | J35: MET | K35: APIS_SSP_v1.1-10-31-2025.docx Assurit_Cyber_Handbook_v2.1-09-08-2025.docx
B36: AC.L2-3.1.11 | C36: 3.1.11 [b] | D36: a user session is automatically terminated after any of the defined conditions occur. | H36: 12/10/2025: Access to Azure Admin Portals and AVD sessions are automatically terminated after 15 minutes of inactivity or when user-initiated. | I36: Implemented | J36: MET | K36: AC.L2-3.1.10b1-12-10-2025.png AC.L2-3.1.10b2-12-10-2025.png
A37: Control Remote Access | B37: AC.L2-3.1.12 | C37: 3.1.12 [a] | D37: remote access sessions are permitted. | E37: Examine: [SELECT FROM: Access control policy; procedures addressing remote access implementation and usage (including restrictions); configuration management plan; system security plan; system design documentation; system configuration settings and associated documentation; remote access authorizations; system audit logs and records; other relevant documents or records]. | F37: Interview: [SELECT FROM: Personnel with responsibilities for managing remote access connections; system or network administrators; personnel with information security responsibilities]. | G37: Test: [SELECT FROM: Remote access management capability for the system]. | H37: 12/10/2025: Remote access sessions are permitted and defined within the Cyber Handbook. | I37: Implemented | J37: MET | K37: APIS_SSP_v1.1-10-31-2025.docx Assurit_Cyber_Handbook_v2.1-09-08-2025.docx
B38: AC.L2-3.1.12 | C38: 3.1.12 [b] | D38: the types of permitted remote access are identified. | H38: 12/10/2025: The Cyber handbook identifies Remote Desktop Protocol (RDP) via Azure Virtual Desktop is the only permitted remote access method. | I38: Implemented | J38: MET | K38: APIS_SSP_v1.1-10-31-2025.docx Assurit_Cyber_Handbook_v2.1-09-08-2025.docx
B39: AC.L2-3.1.12 | C39: 3.1.12 [c] | D39: remote access sessions are controlled. | H39: 12/10/2025: Remote access sessions to AVD are controlled through multiple, combined settings to ensure that only authorized users are able to remotely access AVD resources: 1. Entra ID credentials and conditional access controls are implemented to ensure authorized users and their locations can initiate a remote connection. 2. AVD IAM settings are configured to allow remote connections for assets assigned to each user. AVD assignments is 1:1 to authorized users. 3. Intune Configuration Policies are configured to harden AVD remote access sessions to DISA STIG requirements (Win11V5R2) | I39: Implemented | J39: MET | K39: AC.L2-3.1.12c1-12-06-2025.png AC.L2-3.1.12c2-12-06-2025.png AC.L2-3.1.12c3-12-06-2025.png AC.L2-3.1.12c4-12-06-2025.png AC.L2-3.1.12c5-12-06-2025.png
B40: AC.L2-3.1.12 | C40: 3.1.12 [d] | D40: remote access sessions are monitored. | H40: 12/10/2025: Remote access is monitored through two primary log sources: 1. Entra ID Sign-In Logs monitor interactive sign-ins intiated through AVD remote connections. 2. Windows Event Logs monitor for user's activities and actions while they are remotely connected to the AVD. 3. Logs are forwarded to Microsoft Sentinel with configured rules to monitor for suspicious activity. | I40: Implemented | J40: MET | K40: AC.L2-3.1.12c1-12-06-2025.png AC.L2-3.1.12c2-12-06-2025.png AC.L2-3.1.12c3-12-06-2025.png AC.L2-3.1.12c4-12-06-2025.png AC.L2-3.1.12c5-12-06-2025.png
...

Sheet AT
A1: Practice Name | B1: Practice ID | C1: Procedure ID | D1: Assessment Objective/Determine if: | E1: EXAMINE | F1: INTERVIEW | G1: TEST | H1: Observation Statement | I1: Implementation Status | J1: Assessment Result | K1: Evidence/Artifacts
A2: Role-Based Risk Awareness | B2: AT.L2-3.2.1 | C2: 3.2.1 [a] | D2: security risks associated with organizational activities involving CUI are identified; | E2: Examine: [SELECT FROM: Security awareness and training policy; procedures addressing security awareness training implementation; relevant codes of federal regulations; security awareness training curriculum; security awareness training materials; system security plan; training records; other relevant documents or records]. | F2: Interview: [SELECT FROM: Personnel with responsibilities for security awareness training; personnel with information security responsibilities; personnel composing the general system user community; personnel with responsibilities for role-based awareness training]. | G2: Test: [SELECT FROM: Mechanisms managing security awareness training; mechanisms managing role-based security training]. | H2: 11/11/2025: Assurit implements a security training program and Insider Threat Program that addresses risks involving CUI. The program encompasses computer-based training sessions regarding the management, handling, and monitoring of risks associated to CUI which includes insider threats. It is required by policy that all Assurit employees and contractors that hold security clearances to complete the training upon employment and annually thereafter. When completed, participants are required to sign and acknowledge the policies and requirements for holding a position that requires a security clearance. | I2: Implemented | J2: MET | K2: APIS_SSP_v1.1-10-31-2025.docx Assurit_Cyber_Handbook_v2.1-09-08-2025.docx ASSURIT-ITP-01 (Insider Threat Plan) V2.0.pdf ASSURIT-SPP-01 (Standard Practice Procedures) V2.0.pdf 2024 Annual Security Refresher Training To Be Completed By 9 February 2024.msg 2025 Annual Security Refresher Training To Be Completed By 26 September 2025
B3: AT.L2-3.2.1 | C3: 3.2.1 [b] | D3: policies, standards, and procedures related to the security of the system are identified; | H3: 11/11/2025: Assurit implements a security training program and Insider Threat Program that addresses risks involving CUI. The program encompasses computer-based training sessions regarding the management, handling, and monitoring of risks associated to CUI which includes insider threats. It is required by policy that all Assurit employees and contractors that hold security clearances to complete the training upon employment and annually thereafter. When completed, participants are required to sign and acknowledge the policies and requirements for holding a position that requires a security clearance. | I3: Implemented | J3: MET | K3: APIS_SSP_v1.1-10-31-2025.docx Assurit_Cyber_Handbook_v2.1-09-08-2025.docx ASSURIT-ITP-01 (Insider Threat Plan) V2.0.pdf ASSURIT-SPP-01 (Standard Practice Procedures) V2.0.pdf 2024 Annual Security Refresher Training To Be Completed By 9 February 2024.msg 2025 Annual Security Refresher Training To Be Completed By 26 September 2025
B4: AT.L2-3.2.1 | C4: 3.2.1 [c] | D4: managers, systems administrators, and users of the system are made aware of the security risks associated with their activities. | H4: 11/11/2025: Assurit implements a security training program and Insider Threat Program that addresses risks involving CUI. The program encompasses computer-based training sessions regarding the management, handling, and monitoring of risks associated to CUI which includes insider threats. It is required by policy that all Assurit employees and contractors that hold security clearances to complete the training upon employment and annually thereafter. When completed, participants are required to sign and acknowledge the policies and requirements for holding a position that requires a security clearance. | I4: Implemented | J4: MET | K4: APIS_SSP_v1.1-10-31-2025.docx Assurit_Cyber_Handbook_v2.1-09-08-2025.docx ASSURIT-ITP-01 (Insider Threat Plan) V2.0.pdf ASSURIT-SPP-01 (Standard Practice Procedures) V2.0.pdf 2024 Annual Security Refresher Training To Be Completed By 9 February 2024.msg 2025 Annual Security Refresher Training To Be Completed By 26 September 2025
B5: AT.L2-3.2.1 | C5: 3.2.1 [d] | D5: managers, systems administrators, and users of the system are made aware of the applicable policies, standards, and procedures related to the security of the system. | H5: 11/11/2025: Assurit implements a security training program and Insider Threat Program that addresses risks involving CUI. The program encompasses computer-based training sessions regarding the management, handling, and monitoring of risks associated to CUI which includes insider threats. It is required by policy that all Assurit employees and contractors that hold security clearances to complete the training upon employment and annually thereafter. When completed, participants are required to sign and acknowledge the policies and requirements for holding a position that requires a security clearance. | I5: Implemented | J5: MET | K5: APIS_SSP_v1.1-10-31-2025.docx Assurit_Cyber_Handbook_v2.1-09-08-2025.docx ASSURIT-ITP-01 (Insider Threat Plan) V2.0.pdf ASSURIT-SPP-01 (Standard Practice Procedures) V2.0.pdf 2024 Annual Security Refresher Training To Be Completed By 9 February 2024.msg 2025 Annual Security Refresher Training To Be Completed By 26 September 2025
